[2021-02-25 11:47:29 +0200] [23835] [INFO] Starting gunicorn 20.0.4
[2021-02-25 11:47:29 +0200] [23835] [INFO] Listening at: http://127.0.0.1:8000 (23835)
[2021-02-25 11:47:29 +0200] [23835] [INFO] Using worker: sync
[2021-02-25 11:47:29 +0200] [23840] [INFO] Booting worker with pid: 23840
[2021-02-25 11:47:29 +0200] [23840] [ERROR] Exception in worker process
Traceback (most recent call last):
  File "/home/yoga/lib/python3.6/site-packages/gunicorn/arbiter.py", line 583, in spawn_worker
    worker.init_process()
  File "/home/yoga/lib/python3.6/site-packages/gunicorn/workers/base.py", line 119, in init_process
    self.load_wsgi()
  File "/home/yoga/lib/python3.6/site-packages/gunicorn/workers/base.py", line 144, in load_wsgi
    self.wsgi = self.app.wsgi()
  File "/home/yoga/lib/python3.6/site-packages/gunicorn/app/base.py", line 67, in wsgi
    self.callable = self.load()
  File "/home/yoga/lib/python3.6/site-packages/gunicorn/app/wsgiapp.py", line 49, in load
    return self.load_wsgiapp()
  File "/home/yoga/lib/python3.6/site-packages/gunicorn/app/wsgiapp.py", line 39, in load_wsgiapp
    return util.import_app(self.app_uri)
  File "/home/yoga/lib/python3.6/site-packages/gunicorn/util.py", line 358, in import_app
    mod = importlib.import_module(module)
  File "/usr/lib/python3.6/importlib/__init__.py", line 126, in import_module
    return _bootstrap._gcd_import(name[level:], package, level)
  File "<frozen importlib._bootstrap>", line 994, in _gcd_import
  File "<frozen importlib._bootstrap>", line 971, in _find_and_load
  File "<frozen importlib._bootstrap>", line 941, in _find_and_load_unlocked
  File "<frozen importlib._bootstrap>", line 219, in _call_with_frames_removed
  File "<frozen importlib._bootstrap>", line 994, in _gcd_import
  File "<frozen importlib._bootstrap>", line 971, in _find_and_load
  File "<frozen importlib._bootstrap>", line 953, in _find_and_load_unlocked
ModuleNotFoundError: No module named 'ypga_back'
[2021-02-25 11:47:29 +0200] [23840] [INFO] Worker exiting (pid: 23840)
[2021-02-25 11:47:29 +0200] [23835] [INFO] Shutting down: Master
[2021-02-25 11:47:29 +0200] [23835] [INFO] Reason: Worker failed to boot.
[2021-02-25 11:47:30 +0200] [23841] [INFO] Starting gunicorn 20.0.4
[2021-02-25 11:47:30 +0200] [23841] [INFO] Listening at: http://127.0.0.1:8000 (23841)
[2021-02-25 11:47:30 +0200] [23841] [INFO] Using worker: sync
[2021-02-25 11:47:30 +0200] [23844] [INFO] Booting worker with pid: 23844
[2021-02-25 11:47:30 +0200] [23844] [ERROR] Exception in worker process
Traceback (most recent call last):
  File "/home/yoga/lib/python3.6/site-packages/gunicorn/arbiter.py", line 583, in spawn_worker
    worker.init_process()
  File "/home/yoga/lib/python3.6/site-packages/gunicorn/workers/base.py", line 119, in init_process
    self.load_wsgi()
  File "/home/yoga/lib/python3.6/site-packages/gunicorn/workers/base.py", line 144, in load_wsgi
    self.wsgi = self.app.wsgi()
  File "/home/yoga/lib/python3.6/site-packages/gunicorn/app/base.py", line 67, in wsgi
    self.callable = self.load()
  File "/home/yoga/lib/python3.6/site-packages/gunicorn/app/wsgiapp.py", line 49, in load
    return self.load_wsgiapp()
  File "/home/yoga/lib/python3.6/site-packages/gunicorn/app/wsgiapp.py", line 39, in load_wsgiapp
    return util.import_app(self.app_uri)
  File "/home/yoga/lib/python3.6/site-packages/gunicorn/util.py", line 358, in import_app
    mod = importlib.import_module(module)
  File "/usr/lib/python3.6/importlib/__init__.py", line 126, in import_module
    return _bootstrap._gcd_import(name[level:], package, level)
  File "<frozen importlib._bootstrap>", line 994, in _gcd_import
  File "<frozen importlib._bootstrap>", line 971, in _find_and_load
  File "<frozen importlib._bootstrap>", line 941, in _find_and_load_unlocked
  File "<frozen importlib._bootstrap>", line 219, in _call_with_frames_removed
  File "<frozen importlib._bootstrap>", line 994, in _gcd_import
  File "<frozen importlib._bootstrap>", line 971, in _find_and_load
  File "<frozen importlib._bootstrap>", line 953, in _find_and_load_unlocked
ModuleNotFoundError: No module named 'ypga_back'
[2021-02-25 11:47:30 +0200] [23844] [INFO] Worker exiting (pid: 23844)
[2021-02-25 11:47:30 +0200] [23841] [INFO] Shutting down: Master
[2021-02-25 11:47:30 +0200] [23841] [INFO] Reason: Worker failed to boot.
[2021-02-25 11:47:32 +0200] [23846] [INFO] Starting gunicorn 20.0.4
[2021-02-25 11:47:32 +0200] [23846] [INFO] Listening at: http://127.0.0.1:8000 (23846)
[2021-02-25 11:47:32 +0200] [23846] [INFO] Using worker: sync
[2021-02-25 11:47:32 +0200] [23849] [INFO] Booting worker with pid: 23849
[2021-02-25 11:47:32 +0200] [23849] [ERROR] Exception in worker process
Traceback (most recent call last):
  File "/home/yoga/lib/python3.6/site-packages/gunicorn/arbiter.py", line 583, in spawn_worker
    worker.init_process()
  File "/home/yoga/lib/python3.6/site-packages/gunicorn/workers/base.py", line 119, in init_process
    self.load_wsgi()
  File "/home/yoga/lib/python3.6/site-packages/gunicorn/workers/base.py", line 144, in load_wsgi
    self.wsgi = self.app.wsgi()
  File "/home/yoga/lib/python3.6/site-packages/gunicorn/app/base.py", line 67, in wsgi
    self.callable = self.load()
  File "/home/yoga/lib/python3.6/site-packages/gunicorn/app/wsgiapp.py", line 49, in load
    return self.load_wsgiapp()
  File "/home/yoga/lib/python3.6/site-packages/gunicorn/app/wsgiapp.py", line 39, in load_wsgiapp
    return util.import_app(self.app_uri)
  File "/home/yoga/lib/python3.6/site-packages/gunicorn/util.py", line 358, in import_app
    mod = importlib.import_module(module)
  File "/usr/lib/python3.6/importlib/__init__.py", line 126, in import_module
    return _bootstrap._gcd_import(name[level:], package, level)
  File "<frozen importlib._bootstrap>", line 994, in _gcd_import
  File "<frozen importlib._bootstrap>", line 971, in _find_and_load
  File "<frozen importlib._bootstrap>", line 941, in _find_and_load_unlocked
  File "<frozen importlib._bootstrap>", line 219, in _call_with_frames_removed
  File "<frozen importlib._bootstrap>", line 994, in _gcd_import
  File "<frozen importlib._bootstrap>", line 971, in _find_and_load
  File "<frozen importlib._bootstrap>", line 953, in _find_and_load_unlocked
ModuleNotFoundError: No module named 'ypga_back'
[2021-02-25 11:47:32 +0200] [23849] [INFO] Worker exiting (pid: 23849)
[2021-02-25 11:47:32 +0200] [23846] [INFO] Shutting down: Master
[2021-02-25 11:47:32 +0200] [23846] [INFO] Reason: Worker failed to boot.
[2021-02-25 11:47:35 +0200] [23851] [INFO] Starting gunicorn 20.0.4
[2021-02-25 11:47:35 +0200] [23851] [INFO] Listening at: http://127.0.0.1:8000 (23851)
[2021-02-25 11:47:35 +0200] [23851] [INFO] Using worker: sync
[2021-02-25 11:47:35 +0200] [23855] [INFO] Booting worker with pid: 23855
[2021-02-25 11:47:35 +0200] [23855] [ERROR] Exception in worker process
Traceback (most recent call last):
  File "/home/yoga/lib/python3.6/site-packages/gunicorn/arbiter.py", line 583, in spawn_worker
    worker.init_process()
  File "/home/yoga/lib/python3.6/site-packages/gunicorn/workers/base.py", line 119, in init_process
    self.load_wsgi()
  File "/home/yoga/lib/python3.6/site-packages/gunicorn/workers/base.py", line 144, in load_wsgi
    self.wsgi = self.app.wsgi()
  File "/home/yoga/lib/python3.6/site-packages/gunicorn/app/base.py", line 67, in wsgi
    self.callable = self.load()
  File "/home/yoga/lib/python3.6/site-packages/gunicorn/app/wsgiapp.py", line 49, in load
    return self.load_wsgiapp()
  File "/home/yoga/lib/python3.6/site-packages/gunicorn/app/wsgiapp.py", line 39, in load_wsgiapp
    return util.import_app(self.app_uri)
  File "/home/yoga/lib/python3.6/site-packages/gunicorn/util.py", line 358, in import_app
    mod = importlib.import_module(module)
  File "/usr/lib/python3.6/importlib/__init__.py", line 126, in import_module
    return _bootstrap._gcd_import(name[level:], package, level)
  File "<frozen importlib._bootstrap>", line 994, in _gcd_import
  File "<frozen importlib._bootstrap>", line 971, in _find_and_load
  File "<frozen importlib._bootstrap>", line 941, in _find_and_load_unlocked
  File "<frozen importlib._bootstrap>", line 219, in _call_with_frames_removed
  File "<frozen importlib._bootstrap>", line 994, in _gcd_import
  File "<frozen importlib._bootstrap>", line 971, in _find_and_load
  File "<frozen importlib._bootstrap>", line 953, in _find_and_load_unlocked
ModuleNotFoundError: No module named 'ypga_back'
[2021-02-25 11:47:35 +0200] [23855] [INFO] Worker exiting (pid: 23855)
[2021-02-25 11:47:35 +0200] [23856] [INFO] Booting worker with pid: 23856
[2021-02-25 11:47:35 +0200] [23856] [ERROR] Exception in worker process
Traceback (most recent call last):
  File "/home/yoga/lib/python3.6/site-packages/gunicorn/arbiter.py", line 583, in spawn_worker
    worker.init_process()
  File "/home/yoga/lib/python3.6/site-packages/gunicorn/workers/base.py", line 119, in init_process
    self.load_wsgi()
  File "/home/yoga/lib/python3.6/site-packages/gunicorn/workers/base.py", line 144, in load_wsgi
    self.wsgi = self.app.wsgi()
  File "/home/yoga/lib/python3.6/site-packages/gunicorn/app/base.py", line 67, in wsgi
    self.callable = self.load()
  File "/home/yoga/lib/python3.6/site-packages/gunicorn/app/wsgiapp.py", line 49, in load
    return self.load_wsgiapp()
  File "/home/yoga/lib/python3.6/site-packages/gunicorn/app/wsgiapp.py", line 39, in load_wsgiapp
    return util.import_app(self.app_uri)
  File "/home/yoga/lib/python3.6/site-packages/gunicorn/util.py", line 358, in import_app
    mod = importlib.import_module(module)
  File "/usr/lib/python3.6/importlib/__init__.py", line 126, in import_module
    return _bootstrap._gcd_import(name[level:], package, level)
  File "<frozen importlib._bootstrap>", line 994, in _gcd_import
  File "<frozen importlib._bootstrap>", line 971, in _find_and_load
  File "<frozen importlib._bootstrap>", line 941, in _find_and_load_unlocked
  File "<frozen importlib._bootstrap>", line 219, in _call_with_frames_removed
  File "<frozen importlib._bootstrap>", line 994, in _gcd_import
  File "<frozen importlib._bootstrap>", line 971, in _find_and_load
  File "<frozen importlib._bootstrap>", line 953, in _find_and_load_unlocked
ModuleNotFoundError: No module named 'ypga_back'
[2021-02-25 11:47:35 +0200] [23856] [INFO] Worker exiting (pid: 23856)
[2021-02-25 11:47:35 +0200] [23851] [INFO] Shutting down: Master
[2021-02-25 11:47:35 +0200] [23851] [INFO] Reason: Worker failed to boot.
[2021-02-25 11:47:52 +0200] [23867] [INFO] Starting gunicorn 20.0.4
[2021-02-25 11:47:52 +0200] [23867] [INFO] Listening at: http://127.0.0.1:8000 (23867)
[2021-02-25 11:47:52 +0200] [23867] [INFO] Using worker: sync
[2021-02-25 11:47:52 +0200] [23870] [INFO] Booting worker with pid: 23870
[2021-02-25 11:47:52 +0200] [23870] [ERROR] Exception in worker process
Traceback (most recent call last):
  File "/home/yoga/lib/python3.6/site-packages/gunicorn/arbiter.py", line 583, in spawn_worker
    worker.init_process()
  File "/home/yoga/lib/python3.6/site-packages/gunicorn/workers/base.py", line 119, in init_process
    self.load_wsgi()
  File "/home/yoga/lib/python3.6/site-packages/gunicorn/workers/base.py", line 144, in load_wsgi
    self.wsgi = self.app.wsgi()
  File "/home/yoga/lib/python3.6/site-packages/gunicorn/app/base.py", line 67, in wsgi
    self.callable = self.load()
  File "/home/yoga/lib/python3.6/site-packages/gunicorn/app/wsgiapp.py", line 49, in load
    return self.load_wsgiapp()
  File "/home/yoga/lib/python3.6/site-packages/gunicorn/app/wsgiapp.py", line 39, in load_wsgiapp
    return util.import_app(self.app_uri)
  File "/home/yoga/lib/python3.6/site-packages/gunicorn/util.py", line 358, in import_app
    mod = importlib.import_module(module)
  File "/usr/lib/python3.6/importlib/__init__.py", line 126, in import_module
    return _bootstrap._gcd_import(name[level:], package, level)
  File "<frozen importlib._bootstrap>", line 994, in _gcd_import
  File "<frozen importlib._bootstrap>", line 971, in _find_and_load
  File "<frozen importlib._bootstrap>", line 941, in _find_and_load_unlocked
  File "<frozen importlib._bootstrap>", line 219, in _call_with_frames_removed
  File "<frozen importlib._bootstrap>", line 994, in _gcd_import
  File "<frozen importlib._bootstrap>", line 971, in _find_and_load
  File "<frozen importlib._bootstrap>", line 953, in _find_and_load_unlocked
ModuleNotFoundError: No module named 'ypga_back'
[2021-02-25 11:47:52 +0200] [23870] [INFO] Worker exiting (pid: 23870)
[2021-02-25 11:47:53 +0200] [23867] [INFO] Shutting down: Master
[2021-02-25 11:47:53 +0200] [23867] [INFO] Reason: Worker failed to boot.
[2021-02-25 11:47:54 +0200] [23871] [INFO] Starting gunicorn 20.0.4
[2021-02-25 11:47:54 +0200] [23871] [INFO] Listening at: http://127.0.0.1:8000 (23871)
[2021-02-25 11:47:54 +0200] [23871] [INFO] Using worker: sync
[2021-02-25 11:47:54 +0200] [23874] [INFO] Booting worker with pid: 23874
[2021-02-25 11:47:54 +0200] [23874] [ERROR] Exception in worker process
Traceback (most recent call last):
  File "/home/yoga/lib/python3.6/site-packages/gunicorn/arbiter.py", line 583, in spawn_worker
    worker.init_process()
  File "/home/yoga/lib/python3.6/site-packages/gunicorn/workers/base.py", line 119, in init_process
    self.load_wsgi()
  File "/home/yoga/lib/python3.6/site-packages/gunicorn/workers/base.py", line 144, in load_wsgi
    self.wsgi = self.app.wsgi()
  File "/home/yoga/lib/python3.6/site-packages/gunicorn/app/base.py", line 67, in wsgi
    self.callable = self.load()
  File "/home/yoga/lib/python3.6/site-packages/gunicorn/app/wsgiapp.py", line 49, in load
    return self.load_wsgiapp()
  File "/home/yoga/lib/python3.6/site-packages/gunicorn/app/wsgiapp.py", line 39, in load_wsgiapp
    return util.import_app(self.app_uri)
  File "/home/yoga/lib/python3.6/site-packages/gunicorn/util.py", line 358, in import_app
    mod = importlib.import_module(module)
  File "/usr/lib/python3.6/importlib/__init__.py", line 126, in import_module
    return _bootstrap._gcd_import(name[level:], package, level)
  File "<frozen importlib._bootstrap>", line 994, in _gcd_import
  File "<frozen importlib._bootstrap>", line 971, in _find_and_load
  File "<frozen importlib._bootstrap>", line 941, in _find_and_load_unlocked
  File "<frozen importlib._bootstrap>", line 219, in _call_with_frames_removed
  File "<frozen importlib._bootstrap>", line 994, in _gcd_import
  File "<frozen importlib._bootstrap>", line 971, in _find_and_load
  File "<frozen importlib._bootstrap>", line 953, in _find_and_load_unlocked
ModuleNotFoundError: No module named 'ypga_back'
[2021-02-25 11:47:54 +0200] [23874] [INFO] Worker exiting (pid: 23874)
[2021-02-25 11:47:54 +0200] [23875] [INFO] Booting worker with pid: 23875
[2021-02-25 11:47:54 +0200] [23875] [ERROR] Exception in worker process
Traceback (most recent call last):
  File "/home/yoga/lib/python3.6/site-packages/gunicorn/arbiter.py", line 583, in spawn_worker
    worker.init_process()
  File "/home/yoga/lib/python3.6/site-packages/gunicorn/workers/base.py", line 119, in init_process
    self.load_wsgi()
  File "/home/yoga/lib/python3.6/site-packages/gunicorn/workers/base.py", line 144, in load_wsgi
    self.wsgi = self.app.wsgi()
  File "/home/yoga/lib/python3.6/site-packages/gunicorn/app/base.py", line 67, in wsgi
    self.callable = self.load()
  File "/home/yoga/lib/python3.6/site-packages/gunicorn/app/wsgiapp.py", line 49, in load
    return self.load_wsgiapp()
  File "/home/yoga/lib/python3.6/site-packages/gunicorn/app/wsgiapp.py", line 39, in load_wsgiapp
    return util.import_app(self.app_uri)
  File "/home/yoga/lib/python3.6/site-packages/gunicorn/util.py", line 358, in import_app
    mod = importlib.import_module(module)
  File "/usr/lib/python3.6/importlib/__init__.py", line 126, in import_module
    return _bootstrap._gcd_import(name[level:], package, level)
  File "<frozen importlib._bootstrap>", line 994, in _gcd_import
  File "<frozen importlib._bootstrap>", line 971, in _find_and_load
  File "<frozen importlib._bootstrap>", line 941, in _find_and_load_unlocked
  File "<frozen importlib._bootstrap>", line 219, in _call_with_frames_removed
  File "<frozen importlib._bootstrap>", line 994, in _gcd_import
  File "<frozen importlib._bootstrap>", line 971, in _find_and_load
  File "<frozen importlib._bootstrap>", line 953, in _find_and_load_unlocked
ModuleNotFoundError: No module named 'ypga_back'
[2021-02-25 11:47:54 +0200] [23875] [INFO] Worker exiting (pid: 23875)
Traceback (most recent call last):
  File "/home/yoga/lib/python3.6/site-packages/gunicorn/arbiter.py", line 202, in run
    self.manage_workers()
  File "/home/yoga/lib/python3.6/site-packages/gunicorn/arbiter.py", line 545, in manage_workers
    self.spawn_workers()
  File "/home/yoga/lib/python3.6/site-packages/gunicorn/arbiter.py", line 617, in spawn_workers
    time.sleep(0.1 * random.random())
  File "/home/yoga/lib/python3.6/site-packages/gunicorn/arbiter.py", line 242, in handle_chld
    self.reap_workers()
  File "/home/yoga/lib/python3.6/site-packages/gunicorn/arbiter.py", line 525, in reap_workers
    raise HaltServer(reason, self.WORKER_BOOT_ERROR)
gunicorn.errors.HaltServer: <HaltServer 'Worker failed to boot.' 3>

During handling of the above exception, another exception occurred:

Traceback (most recent call last):
  File "/home/yoga/bin/gunicorn", line 8, in <module>
    sys.exit(run())
  File "/home/yoga/lib/python3.6/site-packages/gunicorn/app/wsgiapp.py", line 58, in run
    WSGIApplication("%(prog)s [OPTIONS] [APP_MODULE]").run()
  File "/home/yoga/lib/python3.6/site-packages/gunicorn/app/base.py", line 228, in run
    super().run()
  File "/home/yoga/lib/python3.6/site-packages/gunicorn/app/base.py", line 72, in run
    Arbiter(self).run()
  File "/home/yoga/lib/python3.6/site-packages/gunicorn/arbiter.py", line 229, in run
    self.halt(reason=inst.reason, exit_status=inst.exit_status)
  File "/home/yoga/lib/python3.6/site-packages/gunicorn/arbiter.py", line 342, in halt
    self.stop()
  File "/home/yoga/lib/python3.6/site-packages/gunicorn/arbiter.py", line 393, in stop
    time.sleep(0.1)
  File "/home/yoga/lib/python3.6/site-packages/gunicorn/arbiter.py", line 242, in handle_chld
    self.reap_workers()
  File "/home/yoga/lib/python3.6/site-packages/gunicorn/arbiter.py", line 525, in reap_workers
    raise HaltServer(reason, self.WORKER_BOOT_ERROR)
gunicorn.errors.HaltServer: <HaltServer 'Worker failed to boot.' 3>
[2021-02-25 11:47:56 +0200] [23878] [INFO] Starting gunicorn 20.0.4
[2021-02-25 11:47:56 +0200] [23878] [INFO] Listening at: http://127.0.0.1:8000 (23878)
[2021-02-25 11:47:56 +0200] [23878] [INFO] Using worker: sync
[2021-02-25 11:47:56 +0200] [23881] [INFO] Booting worker with pid: 23881
[2021-02-25 11:47:56 +0200] [23881] [ERROR] Exception in worker process
Traceback (most recent call last):
  File "/home/yoga/lib/python3.6/site-packages/gunicorn/arbiter.py", line 583, in spawn_worker
    worker.init_process()
  File "/home/yoga/lib/python3.6/site-packages/gunicorn/workers/base.py", line 119, in init_process
    self.load_wsgi()
  File "/home/yoga/lib/python3.6/site-packages/gunicorn/workers/base.py", line 144, in load_wsgi
    self.wsgi = self.app.wsgi()
  File "/home/yoga/lib/python3.6/site-packages/gunicorn/app/base.py", line 67, in wsgi
    self.callable = self.load()
  File "/home/yoga/lib/python3.6/site-packages/gunicorn/app/wsgiapp.py", line 49, in load
    return self.load_wsgiapp()
  File "/home/yoga/lib/python3.6/site-packages/gunicorn/app/wsgiapp.py", line 39, in load_wsgiapp
    return util.import_app(self.app_uri)
  File "/home/yoga/lib/python3.6/site-packages/gunicorn/util.py", line 358, in import_app
    mod = importlib.import_module(module)
  File "/usr/lib/python3.6/importlib/__init__.py", line 126, in import_module
    return _bootstrap._gcd_import(name[level:], package, level)
  File "<frozen importlib._bootstrap>", line 994, in _gcd_import
  File "<frozen importlib._bootstrap>", line 971, in _find_and_load
  File "<frozen importlib._bootstrap>", line 941, in _find_and_load_unlocked
  File "<frozen importlib._bootstrap>", line 219, in _call_with_frames_removed
  File "<frozen importlib._bootstrap>", line 994, in _gcd_import
  File "<frozen importlib._bootstrap>", line 971, in _find_and_load
  File "<frozen importlib._bootstrap>", line 953, in _find_and_load_unlocked
ModuleNotFoundError: No module named 'ypga_back'
[2021-02-25 11:47:56 +0200] [23881] [INFO] Worker exiting (pid: 23881)
[2021-02-25 11:47:56 +0200] [23882] [INFO] Booting worker with pid: 23882
[2021-02-25 11:47:56 +0200] [23882] [ERROR] Exception in worker process
Traceback (most recent call last):
  File "/home/yoga/lib/python3.6/site-packages/gunicorn/arbiter.py", line 583, in spawn_worker
    worker.init_process()
  File "/home/yoga/lib/python3.6/site-packages/gunicorn/workers/base.py", line 119, in init_process
    self.load_wsgi()
  File "/home/yoga/lib/python3.6/site-packages/gunicorn/workers/base.py", line 144, in load_wsgi
    self.wsgi = self.app.wsgi()
  File "/home/yoga/lib/python3.6/site-packages/gunicorn/app/base.py", line 67, in wsgi
    self.callable = self.load()
  File "/home/yoga/lib/python3.6/site-packages/gunicorn/app/wsgiapp.py", line 49, in load
    return self.load_wsgiapp()
  File "/home/yoga/lib/python3.6/site-packages/gunicorn/app/wsgiapp.py", line 39, in load_wsgiapp
    return util.import_app(self.app_uri)
  File "/home/yoga/lib/python3.6/site-packages/gunicorn/util.py", line 358, in import_app
    mod = importlib.import_module(module)
  File "/usr/lib/python3.6/importlib/__init__.py", line 126, in import_module
    return _bootstrap._gcd_import(name[level:], package, level)
  File "<frozen importlib._bootstrap>", line 994, in _gcd_import
  File "<frozen importlib._bootstrap>", line 971, in _find_and_load
  File "<frozen importlib._bootstrap>", line 941, in _find_and_load_unlocked
  File "<frozen importlib._bootstrap>", line 219, in _call_with_frames_removed
  File "<frozen importlib._bootstrap>", line 994, in _gcd_import
  File "<frozen importlib._bootstrap>", line 971, in _find_and_load
  File "<frozen importlib._bootstrap>", line 953, in _find_and_load_unlocked
ModuleNotFoundError: No module named 'ypga_back'
[2021-02-25 11:47:56 +0200] [23882] [INFO] Worker exiting (pid: 23882)
[2021-02-25 11:47:56 +0200] [23883] [INFO] Booting worker with pid: 23883
[2021-02-25 11:47:56 +0200] [23883] [ERROR] Exception in worker process
Traceback (most recent call last):
  File "/home/yoga/lib/python3.6/site-packages/gunicorn/arbiter.py", line 583, in spawn_worker
    worker.init_process()
  File "/home/yoga/lib/python3.6/site-packages/gunicorn/workers/base.py", line 119, in init_process
    self.load_wsgi()
  File "/home/yoga/lib/python3.6/site-packages/gunicorn/workers/base.py", line 144, in load_wsgi
    self.wsgi = self.app.wsgi()
  File "/home/yoga/lib/python3.6/site-packages/gunicorn/app/base.py", line 67, in wsgi
    self.callable = self.load()
  File "/home/yoga/lib/python3.6/site-packages/gunicorn/app/wsgiapp.py", line 49, in load
    return self.load_wsgiapp()
  File "/home/yoga/lib/python3.6/site-packages/gunicorn/app/wsgiapp.py", line 39, in load_wsgiapp
    return util.import_app(self.app_uri)
  File "/home/yoga/lib/python3.6/site-packages/gunicorn/util.py", line 358, in import_app
    mod = importlib.import_module(module)
  File "/usr/lib/python3.6/importlib/__init__.py", line 126, in import_module
    return _bootstrap._gcd_import(name[level:], package, level)
  File "<frozen importlib._bootstrap>", line 994, in _gcd_import
  File "<frozen importlib._bootstrap>", line 971, in _find_and_load
  File "<frozen importlib._bootstrap>", line 941, in _find_and_load_unlocked
  File "<frozen importlib._bootstrap>", line 219, in _call_with_frames_removed
  File "<frozen importlib._bootstrap>", line 994, in _gcd_import
  File "<frozen importlib._bootstrap>", line 971, in _find_and_load
  File "<frozen importlib._bootstrap>", line 953, in _find_and_load_unlocked
ModuleNotFoundError: No module named 'ypga_back'
[2021-02-25 11:47:56 +0200] [23883] [INFO] Worker exiting (pid: 23883)
Traceback (most recent call last):
  File "/home/yoga/lib/python3.6/site-packages/gunicorn/arbiter.py", line 202, in run
    self.manage_workers()
  File "/home/yoga/lib/python3.6/site-packages/gunicorn/arbiter.py", line 545, in manage_workers
    self.spawn_workers()
  File "/home/yoga/lib/python3.6/site-packages/gunicorn/arbiter.py", line 617, in spawn_workers
    time.sleep(0.1 * random.random())
  File "/home/yoga/lib/python3.6/site-packages/gunicorn/arbiter.py", line 242, in handle_chld
    self.reap_workers()
  File "/home/yoga/lib/python3.6/site-packages/gunicorn/arbiter.py", line 525, in reap_workers
    raise HaltServer(reason, self.WORKER_BOOT_ERROR)
gunicorn.errors.HaltServer: <HaltServer 'Worker failed to boot.' 3>

During handling of the above exception, another exception occurred:

Traceback (most recent call last):
  File "/home/yoga/bin/gunicorn", line 8, in <module>
    sys.exit(run())
  File "/home/yoga/lib/python3.6/site-packages/gunicorn/app/wsgiapp.py", line 58, in run
    WSGIApplication("%(prog)s [OPTIONS] [APP_MODULE]").run()
  File "/home/yoga/lib/python3.6/site-packages/gunicorn/app/base.py", line 228, in run
    super().run()
  File "/home/yoga/lib/python3.6/site-packages/gunicorn/app/base.py", line 72, in run
    Arbiter(self).run()
  File "/home/yoga/lib/python3.6/site-packages/gunicorn/arbiter.py", line 229, in run
    self.halt(reason=inst.reason, exit_status=inst.exit_status)
  File "/home/yoga/lib/python3.6/site-packages/gunicorn/arbiter.py", line 342, in halt
    self.stop()
  File "/home/yoga/lib/python3.6/site-packages/gunicorn/arbiter.py", line 393, in stop
    time.sleep(0.1)
  File "/home/yoga/lib/python3.6/site-packages/gunicorn/arbiter.py", line 242, in handle_chld
    self.reap_workers()
  File "/home/yoga/lib/python3.6/site-packages/gunicorn/arbiter.py", line 525, in reap_workers
    raise HaltServer(reason, self.WORKER_BOOT_ERROR)
gunicorn.errors.HaltServer: <HaltServer 'Worker failed to boot.' 3>
[2021-02-25 11:47:59 +0200] [23884] [INFO] Starting gunicorn 20.0.4
[2021-02-25 11:47:59 +0200] [23884] [INFO] Listening at: http://127.0.0.1:8000 (23884)
[2021-02-25 11:47:59 +0200] [23884] [INFO] Using worker: sync
[2021-02-25 11:47:59 +0200] [23887] [INFO] Booting worker with pid: 23887
[2021-02-25 11:47:59 +0200] [23887] [ERROR] Exception in worker process
Traceback (most recent call last):
  File "/home/yoga/lib/python3.6/site-packages/gunicorn/arbiter.py", line 583, in spawn_worker
    worker.init_process()
  File "/home/yoga/lib/python3.6/site-packages/gunicorn/workers/base.py", line 119, in init_process
    self.load_wsgi()
  File "/home/yoga/lib/python3.6/site-packages/gunicorn/workers/base.py", line 144, in load_wsgi
    self.wsgi = self.app.wsgi()
  File "/home/yoga/lib/python3.6/site-packages/gunicorn/app/base.py", line 67, in wsgi
    self.callable = self.load()
  File "/home/yoga/lib/python3.6/site-packages/gunicorn/app/wsgiapp.py", line 49, in load
    return self.load_wsgiapp()
  File "/home/yoga/lib/python3.6/site-packages/gunicorn/app/wsgiapp.py", line 39, in load_wsgiapp
    return util.import_app(self.app_uri)
  File "/home/yoga/lib/python3.6/site-packages/gunicorn/util.py", line 358, in import_app
    mod = importlib.import_module(module)
  File "/usr/lib/python3.6/importlib/__init__.py", line 126, in import_module
    return _bootstrap._gcd_import(name[level:], package, level)
  File "<frozen importlib._bootstrap>", line 994, in _gcd_import
  File "<frozen importlib._bootstrap>", line 971, in _find_and_load
  File "<frozen importlib._bootstrap>", line 941, in _find_and_load_unlocked
  File "<frozen importlib._bootstrap>", line 219, in _call_with_frames_removed
  File "<frozen importlib._bootstrap>", line 994, in _gcd_import
  File "<frozen importlib._bootstrap>", line 971, in _find_and_load
  File "<frozen importlib._bootstrap>", line 953, in _find_and_load_unlocked
ModuleNotFoundError: No module named 'ypga_back'
[2021-02-25 11:47:59 +0200] [23887] [INFO] Worker exiting (pid: 23887)
[2021-02-25 11:47:59 +0200] [23884] [INFO] Shutting down: Master
[2021-02-25 11:47:59 +0200] [23884] [INFO] Reason: Worker failed to boot.
[2021-02-25 11:49:53 +0200] [23930] [INFO] Starting gunicorn 20.0.4
[2021-02-25 11:49:53 +0200] [23930] [INFO] Listening at: http://127.0.0.1:8000 (23930)
[2021-02-25 11:49:53 +0200] [23930] [INFO] Using worker: sync
[2021-02-25 11:49:53 +0200] [23933] [INFO] Booting worker with pid: 23933
[2021-02-25 11:49:53 +0200] [23933] [ERROR] Exception in worker process
Traceback (most recent call last):
  File "/home/yoga/lib/python3.6/site-packages/gunicorn/arbiter.py", line 583, in spawn_worker
    worker.init_process()
  File "/home/yoga/lib/python3.6/site-packages/gunicorn/workers/base.py", line 119, in init_process
    self.load_wsgi()
  File "/home/yoga/lib/python3.6/site-packages/gunicorn/workers/base.py", line 144, in load_wsgi
    self.wsgi = self.app.wsgi()
  File "/home/yoga/lib/python3.6/site-packages/gunicorn/app/base.py", line 67, in wsgi
    self.callable = self.load()
  File "/home/yoga/lib/python3.6/site-packages/gunicorn/app/wsgiapp.py", line 49, in load
    return self.load_wsgiapp()
  File "/home/yoga/lib/python3.6/site-packages/gunicorn/app/wsgiapp.py", line 39, in load_wsgiapp
    return util.import_app(self.app_uri)
  File "/home/yoga/lib/python3.6/site-packages/gunicorn/util.py", line 358, in import_app
    mod = importlib.import_module(module)
  File "/usr/lib/python3.6/importlib/__init__.py", line 126, in import_module
    return _bootstrap._gcd_import(name[level:], package, level)
  File "<frozen importlib._bootstrap>", line 994, in _gcd_import
  File "<frozen importlib._bootstrap>", line 971, in _find_and_load
  File "<frozen importlib._bootstrap>", line 941, in _find_and_load_unlocked
  File "<frozen importlib._bootstrap>", line 219, in _call_with_frames_removed
  File "<frozen importlib._bootstrap>", line 994, in _gcd_import
  File "<frozen importlib._bootstrap>", line 971, in _find_and_load
  File "<frozen importlib._bootstrap>", line 953, in _find_and_load_unlocked
ModuleNotFoundError: No module named 'ypga_back'
[2021-02-25 11:49:53 +0200] [23933] [INFO] Worker exiting (pid: 23933)
[2021-02-25 11:49:53 +0200] [23930] [INFO] Shutting down: Master
[2021-02-25 11:49:53 +0200] [23930] [INFO] Reason: Worker failed to boot.
[2021-02-25 11:49:54 +0200] [23934] [INFO] Starting gunicorn 20.0.4
[2021-02-25 11:49:54 +0200] [23934] [INFO] Listening at: http://127.0.0.1:8000 (23934)
[2021-02-25 11:49:54 +0200] [23934] [INFO] Using worker: sync
[2021-02-25 11:49:54 +0200] [23937] [INFO] Booting worker with pid: 23937
[2021-02-25 11:49:54 +0200] [23937] [ERROR] Exception in worker process
Traceback (most recent call last):
  File "/home/yoga/lib/python3.6/site-packages/gunicorn/arbiter.py", line 583, in spawn_worker
    worker.init_process()
  File "/home/yoga/lib/python3.6/site-packages/gunicorn/workers/base.py", line 119, in init_process
    self.load_wsgi()
  File "/home/yoga/lib/python3.6/site-packages/gunicorn/workers/base.py", line 144, in load_wsgi
    self.wsgi = self.app.wsgi()
  File "/home/yoga/lib/python3.6/site-packages/gunicorn/app/base.py", line 67, in wsgi
    self.callable = self.load()
  File "/home/yoga/lib/python3.6/site-packages/gunicorn/app/wsgiapp.py", line 49, in load
    return self.load_wsgiapp()
  File "/home/yoga/lib/python3.6/site-packages/gunicorn/app/wsgiapp.py", line 39, in load_wsgiapp
    return util.import_app(self.app_uri)
  File "/home/yoga/lib/python3.6/site-packages/gunicorn/util.py", line 358, in import_app
    mod = importlib.import_module(module)
  File "/usr/lib/python3.6/importlib/__init__.py", line 126, in import_module
    return _bootstrap._gcd_import(name[level:], package, level)
  File "<frozen importlib._bootstrap>", line 994, in _gcd_import
  File "<frozen importlib._bootstrap>", line 971, in _find_and_load
  File "<frozen importlib._bootstrap>", line 941, in _find_and_load_unlocked
  File "<frozen importlib._bootstrap>", line 219, in _call_with_frames_removed
  File "<frozen importlib._bootstrap>", line 994, in _gcd_import
  File "<frozen importlib._bootstrap>", line 971, in _find_and_load
  File "<frozen importlib._bootstrap>", line 953, in _find_and_load_unlocked
ModuleNotFoundError: No module named 'ypga_back'
[2021-02-25 11:49:54 +0200] [23937] [INFO] Worker exiting (pid: 23937)
[2021-02-25 11:49:54 +0200] [23934] [INFO] Shutting down: Master
[2021-02-25 11:49:54 +0200] [23934] [INFO] Reason: Worker failed to boot.
[2021-02-25 11:49:56 +0200] [23938] [INFO] Starting gunicorn 20.0.4
[2021-02-25 11:49:56 +0200] [23938] [INFO] Listening at: http://127.0.0.1:8000 (23938)
[2021-02-25 11:49:56 +0200] [23938] [INFO] Using worker: sync
[2021-02-25 11:49:56 +0200] [23941] [INFO] Booting worker with pid: 23941
[2021-02-25 11:49:56 +0200] [23941] [ERROR] Exception in worker process
Traceback (most recent call last):
  File "/home/yoga/lib/python3.6/site-packages/gunicorn/arbiter.py", line 583, in spawn_worker
    worker.init_process()
  File "/home/yoga/lib/python3.6/site-packages/gunicorn/workers/base.py", line 119, in init_process
    self.load_wsgi()
  File "/home/yoga/lib/python3.6/site-packages/gunicorn/workers/base.py", line 144, in load_wsgi
    self.wsgi = self.app.wsgi()
  File "/home/yoga/lib/python3.6/site-packages/gunicorn/app/base.py", line 67, in wsgi
    self.callable = self.load()
  File "/home/yoga/lib/python3.6/site-packages/gunicorn/app/wsgiapp.py", line 49, in load
    return self.load_wsgiapp()
  File "/home/yoga/lib/python3.6/site-packages/gunicorn/app/wsgiapp.py", line 39, in load_wsgiapp
    return util.import_app(self.app_uri)
  File "/home/yoga/lib/python3.6/site-packages/gunicorn/util.py", line 358, in import_app
    mod = importlib.import_module(module)
  File "/usr/lib/python3.6/importlib/__init__.py", line 126, in import_module
    return _bootstrap._gcd_import(name[level:], package, level)
  File "<frozen importlib._bootstrap>", line 994, in _gcd_import
  File "<frozen importlib._bootstrap>", line 971, in _find_and_load
  File "<frozen importlib._bootstrap>", line 941, in _find_and_load_unlocked
  File "<frozen importlib._bootstrap>", line 219, in _call_with_frames_removed
  File "<frozen importlib._bootstrap>", line 994, in _gcd_import
  File "<frozen importlib._bootstrap>", line 971, in _find_and_load
  File "<frozen importlib._bootstrap>", line 953, in _find_and_load_unlocked
ModuleNotFoundError: No module named 'ypga_back'
[2021-02-25 11:49:56 +0200] [23941] [INFO] Worker exiting (pid: 23941)
[2021-02-25 11:49:56 +0200] [23938] [INFO] Shutting down: Master
[2021-02-25 11:49:56 +0200] [23938] [INFO] Reason: Worker failed to boot.
[2021-02-25 11:49:59 +0200] [23944] [INFO] Starting gunicorn 20.0.4
[2021-02-25 11:49:59 +0200] [23944] [INFO] Listening at: http://127.0.0.1:8000 (23944)
[2021-02-25 11:49:59 +0200] [23944] [INFO] Using worker: sync
[2021-02-25 11:49:59 +0200] [23947] [INFO] Booting worker with pid: 23947
[2021-02-25 11:49:59 +0200] [23947] [ERROR] Exception in worker process
Traceback (most recent call last):
  File "/home/yoga/lib/python3.6/site-packages/gunicorn/arbiter.py", line 583, in spawn_worker
    worker.init_process()
  File "/home/yoga/lib/python3.6/site-packages/gunicorn/workers/base.py", line 119, in init_process
    self.load_wsgi()
  File "/home/yoga/lib/python3.6/site-packages/gunicorn/workers/base.py", line 144, in load_wsgi
    self.wsgi = self.app.wsgi()
  File "/home/yoga/lib/python3.6/site-packages/gunicorn/app/base.py", line 67, in wsgi
    self.callable = self.load()
  File "/home/yoga/lib/python3.6/site-packages/gunicorn/app/wsgiapp.py", line 49, in load
    return self.load_wsgiapp()
  File "/home/yoga/lib/python3.6/site-packages/gunicorn/app/wsgiapp.py", line 39, in load_wsgiapp
    return util.import_app(self.app_uri)
  File "/home/yoga/lib/python3.6/site-packages/gunicorn/util.py", line 358, in import_app
    mod = importlib.import_module(module)
  File "/usr/lib/python3.6/importlib/__init__.py", line 126, in import_module
    return _bootstrap._gcd_import(name[level:], package, level)
  File "<frozen importlib._bootstrap>", line 994, in _gcd_import
  File "<frozen importlib._bootstrap>", line 971, in _find_and_load
  File "<frozen importlib._bootstrap>", line 941, in _find_and_load_unlocked
  File "<frozen importlib._bootstrap>", line 219, in _call_with_frames_removed
  File "<frozen importlib._bootstrap>", line 994, in _gcd_import
  File "<frozen importlib._bootstrap>", line 971, in _find_and_load
  File "<frozen importlib._bootstrap>", line 953, in _find_and_load_unlocked
ModuleNotFoundError: No module named 'ypga_back'
[2021-02-25 11:49:59 +0200] [23947] [INFO] Worker exiting (pid: 23947)
[2021-02-25 11:49:59 +0200] [23944] [INFO] Shutting down: Master
[2021-02-25 11:49:59 +0200] [23944] [INFO] Reason: Worker failed to boot.
[2021-02-25 11:50:39 +0200] [23971] [INFO] Starting gunicorn 20.0.4
[2021-02-25 11:50:39 +0200] [23971] [INFO] Listening at: http://127.0.0.1:8000 (23971)
[2021-02-25 11:50:39 +0200] [23971] [INFO] Using worker: sync
[2021-02-25 11:50:39 +0200] [23974] [INFO] Booting worker with pid: 23974
[2021-02-25 11:50:39 +0200] [23976] [INFO] Booting worker with pid: 23976
[2021-02-25 11:50:39 +0200] [23977] [INFO] Booting worker with pid: 23977
[2021-02-25 11:51:00 +0200] [23971] [INFO] Handling signal: term
[2021-02-25 09:51:00 +0000] [23974] [INFO] Worker exiting (pid: 23974)
[2021-02-25 09:51:00 +0000] [23976] [INFO] Worker exiting (pid: 23976)
[2021-02-25 09:51:00 +0000] [23977] [INFO] Worker exiting (pid: 23977)
[2021-02-25 11:51:00 +0200] [23971] [INFO] Shutting down: Master
[2021-02-25 11:51:00 +0200] [23989] [INFO] Starting gunicorn 20.0.4
[2021-02-25 11:51:00 +0200] [23989] [INFO] Listening at: http://127.0.0.1:8000 (23989)
[2021-02-25 11:51:00 +0200] [23989] [INFO] Using worker: sync
[2021-02-25 11:51:00 +0200] [23992] [INFO] Booting worker with pid: 23992
[2021-02-25 11:51:00 +0200] [23994] [INFO] Booting worker with pid: 23994
[2021-02-25 11:51:01 +0200] [23996] [INFO] Booting worker with pid: 23996
Internal Server Error: /admin/workout/trouble/1/change/
Traceback (most recent call last):
  File "/home/yoga/lib/python3.6/site-packages/django/core/handlers/exception.py", line 47, in inner
    response = get_response(request)
  File "/home/yoga/lib/python3.6/site-packages/django/core/handlers/base.py", line 181, in _get_response
    response = wrapped_callback(request, *callback_args, **callback_kwargs)
  File "/home/yoga/lib/python3.6/site-packages/django/contrib/admin/options.py", line 614, in wrapper
    return self.admin_site.admin_view(view)(*args, **kwargs)
  File "/home/yoga/lib/python3.6/site-packages/django/utils/decorators.py", line 130, in _wrapped_view
    response = view_func(request, *args, **kwargs)
  File "/home/yoga/lib/python3.6/site-packages/django/views/decorators/cache.py", line 44, in _wrapped_view_func
    response = view_func(request, *args, **kwargs)
  File "/home/yoga/lib/python3.6/site-packages/django/contrib/admin/sites.py", line 233, in inner
    return view(request, *args, **kwargs)
  File "/home/yoga/lib/python3.6/site-packages/django/contrib/admin/options.py", line 1656, in change_view
    return self.changeform_view(request, object_id, form_url, extra_context)
  File "/home/yoga/lib/python3.6/site-packages/django/utils/decorators.py", line 43, in _wrapper
    return bound_method(*args, **kwargs)
  File "/home/yoga/lib/python3.6/site-packages/django/utils/decorators.py", line 130, in _wrapped_view
    response = view_func(request, *args, **kwargs)
  File "/home/yoga/lib/python3.6/site-packages/django/contrib/admin/options.py", line 1534, in changeform_view
    return self._changeform_view(request, object_id, form_url, extra_context)
  File "/home/yoga/lib/python3.6/site-packages/django/contrib/admin/options.py", line 1580, in _changeform_view
    self.save_model(request, new_object, form, not add)
  File "/home/yoga/lib/python3.6/site-packages/django/contrib/admin/options.py", line 1093, in save_model
    obj.save()
  File "/home/yoga/lib/python3.6/site-packages/django/db/models/base.py", line 754, in save
    force_update=force_update, update_fields=update_fields)
  File "/home/yoga/lib/python3.6/site-packages/django/db/models/base.py", line 792, in save_base
    force_update, using, update_fields,
  File "/home/yoga/lib/python3.6/site-packages/django/db/models/base.py", line 870, in _save_table
    for f in non_pks]
  File "/home/yoga/lib/python3.6/site-packages/django/db/models/base.py", line 870, in <listcomp>
    for f in non_pks]
  File "/home/yoga/lib/python3.6/site-packages/django/db/models/fields/files.py", line 307, in pre_save
    file.save(file.name, file.file, save=False)
  File "/home/yoga/lib/python3.6/site-packages/django/db/models/fields/files.py", line 87, in save
    self.name = self.storage.save(name, content, max_length=self.field.max_length)
  File "/home/yoga/lib/python3.6/site-packages/django/core/files/storage.py", line 52, in save
    return self._save(name, content)
  File "/home/yoga/lib/python3.6/site-packages/django/core/files/storage.py", line 267, in _save
    fd = os.open(full_path, self.OS_OPEN_FLAGS, 0o666)
PermissionError: [Errno 13] Permission denied: '/home/yoga_vue_django/yoga_back/media/kotik_T5Ho0oc.jpg'
Internal Server Error: /admin/workout/trouble/1/change/
Traceback (most recent call last):
  File "/home/yoga/lib/python3.6/site-packages/django/core/handlers/exception.py", line 47, in inner
    response = get_response(request)
  File "/home/yoga/lib/python3.6/site-packages/django/core/handlers/base.py", line 181, in _get_response
    response = wrapped_callback(request, *callback_args, **callback_kwargs)
  File "/home/yoga/lib/python3.6/site-packages/django/contrib/admin/options.py", line 614, in wrapper
    return self.admin_site.admin_view(view)(*args, **kwargs)
  File "/home/yoga/lib/python3.6/site-packages/django/utils/decorators.py", line 130, in _wrapped_view
    response = view_func(request, *args, **kwargs)
  File "/home/yoga/lib/python3.6/site-packages/django/views/decorators/cache.py", line 44, in _wrapped_view_func
    response = view_func(request, *args, **kwargs)
  File "/home/yoga/lib/python3.6/site-packages/django/contrib/admin/sites.py", line 233, in inner
    return view(request, *args, **kwargs)
  File "/home/yoga/lib/python3.6/site-packages/django/contrib/admin/options.py", line 1656, in change_view
    return self.changeform_view(request, object_id, form_url, extra_context)
  File "/home/yoga/lib/python3.6/site-packages/django/utils/decorators.py", line 43, in _wrapper
    return bound_method(*args, **kwargs)
  File "/home/yoga/lib/python3.6/site-packages/django/utils/decorators.py", line 130, in _wrapped_view
    response = view_func(request, *args, **kwargs)
  File "/home/yoga/lib/python3.6/site-packages/django/contrib/admin/options.py", line 1534, in changeform_view
    return self._changeform_view(request, object_id, form_url, extra_context)
  File "/home/yoga/lib/python3.6/site-packages/django/contrib/admin/options.py", line 1580, in _changeform_view
    self.save_model(request, new_object, form, not add)
  File "/home/yoga/lib/python3.6/site-packages/django/contrib/admin/options.py", line 1093, in save_model
    obj.save()
  File "/home/yoga/lib/python3.6/site-packages/django/db/models/base.py", line 754, in save
    force_update=force_update, update_fields=update_fields)
  File "/home/yoga/lib/python3.6/site-packages/django/db/models/base.py", line 792, in save_base
    force_update, using, update_fields,
  File "/home/yoga/lib/python3.6/site-packages/django/db/models/base.py", line 870, in _save_table
    for f in non_pks]
  File "/home/yoga/lib/python3.6/site-packages/django/db/models/base.py", line 870, in <listcomp>
    for f in non_pks]
  File "/home/yoga/lib/python3.6/site-packages/django/db/models/fields/files.py", line 307, in pre_save
    file.save(file.name, file.file, save=False)
  File "/home/yoga/lib/python3.6/site-packages/django/db/models/fields/files.py", line 87, in save
    self.name = self.storage.save(name, content, max_length=self.field.max_length)
  File "/home/yoga/lib/python3.6/site-packages/django/core/files/storage.py", line 52, in save
    return self._save(name, content)
  File "/home/yoga/lib/python3.6/site-packages/django/core/files/storage.py", line 267, in _save
    fd = os.open(full_path, self.OS_OPEN_FLAGS, 0o666)
PermissionError: [Errno 13] Permission denied: '/home/yoga_vue_django/yoga_back/media/kotik.jpg'
Not Found: /robots.txt
Not Found: /robots.txt
Not Found: /favicon.ico
[2021-02-25 12:02:17 +0200] [23989] [INFO] Handling signal: term
[2021-02-25 10:02:17 +0000] [23992] [INFO] Worker exiting (pid: 23992)
[2021-02-25 10:02:17 +0000] [23994] [INFO] Worker exiting (pid: 23994)
[2021-02-25 10:02:17 +0000] [23996] [INFO] Worker exiting (pid: 23996)
[2021-02-25 12:02:18 +0200] [23989] [INFO] Shutting down: Master
[2021-02-25 12:02:18 +0200] [24119] [INFO] Starting gunicorn 20.0.4
[2021-02-25 12:02:18 +0200] [24119] [INFO] Listening at: http://127.0.0.1:8000 (24119)
[2021-02-25 12:02:18 +0200] [24119] [INFO] Using worker: sync
[2021-02-25 12:02:18 +0200] [24122] [INFO] Booting worker with pid: 24122
[2021-02-25 12:02:18 +0200] [24123] [INFO] Booting worker with pid: 24123
[2021-02-25 12:02:18 +0200] [24126] [INFO] Booting worker with pid: 24126
[2021-02-25 12:08:04 +0200] [24119] [INFO] Handling signal: term
[2021-02-25 10:08:04 +0000] [24122] [INFO] Worker exiting (pid: 24122)
[2021-02-25 10:08:04 +0000] [24123] [INFO] Worker exiting (pid: 24123)
[2021-02-25 10:08:04 +0000] [24126] [INFO] Worker exiting (pid: 24126)
[2021-02-25 12:08:04 +0200] [24119] [INFO] Shutting down: Master
[2021-02-25 12:08:04 +0200] [24169] [INFO] Starting gunicorn 20.0.4
[2021-02-25 12:08:04 +0200] [24169] [INFO] Listening at: http://127.0.0.1:8000 (24169)
[2021-02-25 12:08:04 +0200] [24169] [INFO] Using worker: sync
[2021-02-25 12:08:04 +0200] [24172] [INFO] Booting worker with pid: 24172
[2021-02-25 12:08:04 +0200] [24174] [INFO] Booting worker with pid: 24174
[2021-02-25 12:08:04 +0200] [24175] [INFO] Booting worker with pid: 24175
Not Found: /robots.txt
Not Found: /robots.txt
Not Found: /favicon.ico
[2021-02-25 12:12:21 +0200] [24169] [INFO] Handling signal: term
[2021-02-25 10:12:21 +0000] [24172] [INFO] Worker exiting (pid: 24172)
[2021-02-25 10:12:21 +0000] [24174] [INFO] Worker exiting (pid: 24174)
[2021-02-25 10:12:21 +0000] [24175] [INFO] Worker exiting (pid: 24175)
[2021-02-25 12:12:22 +0200] [24169] [INFO] Shutting down: Master
[2021-02-25 12:12:22 +0200] [24226] [INFO] Starting gunicorn 20.0.4
[2021-02-25 12:12:22 +0200] [24226] [INFO] Listening at: http://127.0.0.1:8000 (24226)
[2021-02-25 12:12:22 +0200] [24226] [INFO] Using worker: sync
[2021-02-25 12:12:22 +0200] [24229] [INFO] Booting worker with pid: 24229
[2021-02-25 12:12:22 +0200] [24231] [INFO] Booting worker with pid: 24231
[2021-02-25 12:12:22 +0200] [24233] [INFO] Booting worker with pid: 24233
Not Found: /favicon.ico
Not Found: /favicon.ico
Not Found: /favicon.ico
Not Found: /medi/kotik.jpg
Not Found: /favicon.ico
Not Found: /favicon.ico
Not Found: /favicon.ico
Not Found: /medi/kotik.jpg
Internal Server Error: /apidoc/
Traceback (most recent call last):
  File "/home/yoga/lib/python3.6/site-packages/django/core/handlers/exception.py", line 47, in inner
    response = get_response(request)
  File "/home/yoga/lib/python3.6/site-packages/django/core/handlers/base.py", line 181, in _get_response
    response = wrapped_callback(request, *callback_args, **callback_kwargs)
  File "/home/yoga_vue_django/yoga_back/yoga_back/api_view.py", line 4, in apidoc
    return render(request, 'doc/index.html')
  File "/home/yoga/lib/python3.6/site-packages/django/shortcuts.py", line 19, in render
    content = loader.render_to_string(template_name, context, request, using=using)
  File "/home/yoga/lib/python3.6/site-packages/django/template/loader.py", line 61, in render_to_string
    template = get_template(template_name, using=using)
  File "/home/yoga/lib/python3.6/site-packages/django/template/loader.py", line 19, in get_template
    raise TemplateDoesNotExist(template_name, chain=chain)
django.template.exceptions.TemplateDoesNotExist: doc/index.html
Not Found: /
[2021-02-25 12:39:54 +0200] [24226] [INFO] Handling signal: term
[2021-02-25 10:39:54 +0000] [24229] [INFO] Worker exiting (pid: 24229)
[2021-02-25 10:39:54 +0000] [24231] [INFO] Worker exiting (pid: 24231)
[2021-02-25 10:39:54 +0000] [24233] [INFO] Worker exiting (pid: 24233)
[2021-02-25 12:39:54 +0200] [24226] [INFO] Shutting down: Master
[2021-02-25 12:39:54 +0200] [24723] [INFO] Starting gunicorn 20.0.4
[2021-02-25 12:39:54 +0200] [24723] [INFO] Listening at: http://127.0.0.1:8000 (24723)
[2021-02-25 12:39:54 +0200] [24723] [INFO] Using worker: sync
[2021-02-25 12:39:54 +0200] [24726] [INFO] Booting worker with pid: 24726
[2021-02-25 12:39:54 +0200] [24728] [INFO] Booting worker with pid: 24728
[2021-02-25 12:39:54 +0200] [24729] [INFO] Booting worker with pid: 24729
[2021-02-25 13:28:26 +0200] [25548] [INFO] Starting gunicorn 20.0.4
[2021-02-25 13:28:26 +0200] [25548] [INFO] Listening at: http://127.0.0.1:8000 (25548)
[2021-02-25 13:28:26 +0200] [25548] [INFO] Using worker: sync
[2021-02-25 13:28:26 +0200] [25551] [INFO] Booting worker with pid: 25551
[2021-02-25 13:28:26 +0200] [25552] [INFO] Booting worker with pid: 25552
[2021-02-25 13:28:26 +0200] [25555] [INFO] Booting worker with pid: 25555
Not Found: /index.html
Not Found: /index.html
Not Found: /index.html
Not Found: /index.html
Not Found: /index.html
Not Found: /index.html
Not Found: /index.html
[2021-02-25 15:30:31 +0200] [28740] [INFO] Starting gunicorn 20.0.4
[2021-02-25 15:30:31 +0200] [28740] [INFO] Listening at: http://127.0.0.1:8000 (28740)
[2021-02-25 15:30:31 +0200] [28740] [INFO] Using worker: sync
[2021-02-25 15:30:31 +0200] [28743] [INFO] Booting worker with pid: 28743
[2021-02-25 15:30:31 +0200] [28744] [INFO] Booting worker with pid: 28744
[2021-02-25 15:30:31 +0200] [28747] [INFO] Booting worker with pid: 28747
Method Not Allowed: /api/user/admin-login/
Bad Request: /api/user/admin-login/
Bad Request: /api/user/admin-login/
Bad Request: /api/user/admin-login/
Bad Request: /api/user/admin-login/
[2021-02-25 15:35:37 +0200] [28740] [INFO] Handling signal: term
[2021-02-25 13:35:37 +0000] [28743] [INFO] Worker exiting (pid: 28743)
[2021-02-25 13:35:37 +0000] [28744] [INFO] Worker exiting (pid: 28744)
[2021-02-25 13:35:37 +0000] [28747] [INFO] Worker exiting (pid: 28747)
[2021-02-25 15:35:38 +0200] [28740] [INFO] Shutting down: Master
[2021-02-25 15:35:38 +0200] [28853] [INFO] Starting gunicorn 20.0.4
[2021-02-25 15:35:38 +0200] [28853] [INFO] Listening at: http://127.0.0.1:8000 (28853)
[2021-02-25 15:35:38 +0200] [28853] [INFO] Using worker: sync
[2021-02-25 15:35:38 +0200] [28856] [INFO] Booting worker with pid: 28856
[2021-02-25 15:35:38 +0200] [28858] [INFO] Booting worker with pid: 28858
[2021-02-25 15:35:38 +0200] [28857] [INFO] Booting worker with pid: 28857
Bad Request: /api/user/admin-login/
Bad Request: /api/user/admin-login/
Not Found: /
[2021-02-25 15:39:01 +0200] [28964] [INFO] Starting gunicorn 20.0.4
[2021-02-25 15:39:01 +0200] [28964] [INFO] Listening at: http://127.0.0.1:8000 (28964)
[2021-02-25 15:39:01 +0200] [28964] [INFO] Using worker: sync
[2021-02-25 15:39:01 +0200] [28967] [INFO] Booting worker with pid: 28967
[2021-02-25 15:39:01 +0200] [28969] [INFO] Booting worker with pid: 28969
[2021-02-25 15:39:01 +0200] [28970] [INFO] Booting worker with pid: 28970
[2021-02-25 15:39:54 +0200] [28964] [INFO] Handling signal: term
[2021-02-25 13:39:54 +0000] [28967] [INFO] Worker exiting (pid: 28967)
[2021-02-25 13:39:55 +0000] [28969] [INFO] Worker exiting (pid: 28969)
[2021-02-25 13:39:55 +0000] [28970] [INFO] Worker exiting (pid: 28970)
[2021-02-25 15:39:55 +0200] [28964] [INFO] Shutting down: Master
[2021-02-25 15:39:55 +0200] [28999] [INFO] Starting gunicorn 20.0.4
[2021-02-25 15:39:55 +0200] [28999] [INFO] Listening at: http://127.0.0.1:8000 (28999)
[2021-02-25 15:39:55 +0200] [28999] [INFO] Using worker: sync
[2021-02-25 15:39:55 +0200] [29002] [INFO] Booting worker with pid: 29002
[2021-02-25 15:39:55 +0200] [29004] [INFO] Booting worker with pid: 29004
[2021-02-25 15:39:55 +0200] [29005] [INFO] Booting worker with pid: 29005
[2021-02-25 15:50:48 +0200] [29408] [INFO] Starting gunicorn 20.0.4
[2021-02-25 15:50:48 +0200] [29408] [INFO] Listening at: http://127.0.0.1:8000 (29408)
[2021-02-25 15:50:48 +0200] [29408] [INFO] Using worker: sync
[2021-02-25 15:50:48 +0200] [29411] [INFO] Booting worker with pid: 29411
[2021-02-25 15:50:48 +0200] [29412] [INFO] Booting worker with pid: 29412
[2021-02-25 15:50:48 +0200] [29415] [INFO] Booting worker with pid: 29415
Unsupported Media Type: /api/user/admin-login/
Unsupported Media Type: /api/user/admin-login/
Unsupported Media Type: /api/user/admin-login/
Unsupported Media Type: /api/user/admin-login/
Unsupported Media Type: /api/user/admin-login/
Unsupported Media Type: /api/user/admin-login/
[2021-02-25 15:53:31 +0200] [29408] [INFO] Handling signal: term
[2021-02-25 13:53:31 +0000] [29411] [INFO] Worker exiting (pid: 29411)
[2021-02-25 13:53:31 +0000] [29412] [INFO] Worker exiting (pid: 29412)
<QueryDict: {'email': ['test@gmail.com'], 'password': ['test']}>
[2021-02-25 13:53:31 +0000] [29415] [INFO] Worker exiting (pid: 29415)
[2021-02-25 15:53:32 +0200] [29408] [INFO] Shutting down: Master
[2021-02-25 15:53:32 +0200] [29472] [INFO] Starting gunicorn 20.0.4
[2021-02-25 15:53:32 +0200] [29472] [INFO] Listening at: http://127.0.0.1:8000 (29472)
[2021-02-25 15:53:32 +0200] [29472] [INFO] Using worker: sync
[2021-02-25 15:53:32 +0200] [29475] [INFO] Booting worker with pid: 29475
[2021-02-25 15:53:32 +0200] [29476] [INFO] Booting worker with pid: 29476
[2021-02-25 15:53:32 +0200] [29479] [INFO] Booting worker with pid: 29479
Unsupported Media Type: /api/user/admin-login/
Unsupported Media Type: /api/user/admin-login/
Unsupported Media Type: /api/user/admin-login/
Not Found: /api-admin/
Not Found: /favicon.ico
Not Found: /
Not Found: /
Internal Server Error: /apidoc/
Traceback (most recent call last):
  File "/home/yoga/lib/python3.6/site-packages/django/core/handlers/exception.py", line 47, in inner
    response = get_response(request)
  File "/home/yoga/lib/python3.6/site-packages/django/core/handlers/base.py", line 181, in _get_response
    response = wrapped_callback(request, *callback_args, **callback_kwargs)
  File "/home/yoga_vue_django/yoga_back/yoga_back/api_view.py", line 4, in apidoc
    return render(request, 'doc/index.html')
  File "/home/yoga/lib/python3.6/site-packages/django/shortcuts.py", line 19, in render
    content = loader.render_to_string(template_name, context, request, using=using)
  File "/home/yoga/lib/python3.6/site-packages/django/template/loader.py", line 61, in render_to_string
    template = get_template(template_name, using=using)
  File "/home/yoga/lib/python3.6/site-packages/django/template/loader.py", line 19, in get_template
    raise TemplateDoesNotExist(template_name, chain=chain)
django.template.exceptions.TemplateDoesNotExist: doc/index.html
Not Found: /
Not Found: /
Not Found: /wp-includes/wlwmanifest.xml
Not Found: /xmlrpc.php
Not Found: /
Not Found: /blog/wp-includes/wlwmanifest.xml
Not Found: /web/wp-includes/wlwmanifest.xml
Not Found: /wordpress/wp-includes/wlwmanifest.xml
Not Found: /website/wp-includes/wlwmanifest.xml
Not Found: /wp/wp-includes/wlwmanifest.xml
Not Found: /news/wp-includes/wlwmanifest.xml
Not Found: /wp1/wp-includes/wlwmanifest.xml
Not Found: /test/wp-includes/wlwmanifest.xml
Not Found: /wp2/wp-includes/wlwmanifest.xml
Not Found: /site/wp-includes/wlwmanifest.xml
Not Found: /cms/wp-includes/wlwmanifest.xml
Not Found: /sito/wp-includes/wlwmanifest.xml
Unsupported Media Type: /api/user/admin-login/
Not Found: /
Not Found: /wp-includes/wlwmanifest.xml
Not Found: /xmlrpc.php
Not Found: /
Not Found: /blog/wp-includes/wlwmanifest.xml
Not Found: /web/wp-includes/wlwmanifest.xml
Not Found: /wordpress/wp-includes/wlwmanifest.xml
Not Found: /website/wp-includes/wlwmanifest.xml
Not Found: /wp/wp-includes/wlwmanifest.xml
Not Found: /news/wp-includes/wlwmanifest.xml
Not Found: /wp1/wp-includes/wlwmanifest.xml
Not Found: /test/wp-includes/wlwmanifest.xml
Not Found: /wp2/wp-includes/wlwmanifest.xml
Not Found: /site/wp-includes/wlwmanifest.xml
Not Found: /cms/wp-includes/wlwmanifest.xml
Not Found: /sito/wp-includes/wlwmanifest.xml
Not Found: /
Not Found: /api-admin/
Not Found: /api/
Not Found: /api/workout
Not Found: /api/workout/
Not Found: /
[2021-02-25 16:13:28 +0200] [29472] [INFO] Handling signal: term
[2021-02-25 14:13:28 +0000] [29475] [INFO] Worker exiting (pid: 29475)
[2021-02-25 14:13:28 +0000] [29476] [INFO] Worker exiting (pid: 29476)
[2021-02-25 14:13:28 +0000] [29479] [INFO] Worker exiting (pid: 29479)
[2021-02-25 16:13:28 +0200] [29472] [INFO] Shutting down: Master
[2021-02-25 16:13:29 +0200] [29821] [INFO] Starting gunicorn 20.0.4
[2021-02-25 16:13:29 +0200] [29821] [INFO] Listening at: http://127.0.0.1:8000 (29821)
[2021-02-25 16:13:29 +0200] [29821] [INFO] Using worker: sync
[2021-02-25 16:13:29 +0200] [29824] [INFO] Booting worker with pid: 29824
[2021-02-25 16:13:29 +0200] [29826] [INFO] Booting worker with pid: 29826
[2021-02-25 16:13:29 +0200] [29827] [INFO] Booting worker with pid: 29827
Unsupported Media Type: /api/user/admin-login/
Unsupported Media Type: /api/user/admin-login/
Unsupported Media Type: /api/user/admin-login/
Unsupported Media Type: /api/user/admin-login/
Not Found: /
Not Found: /favicon.ico
Not Found: /
Not Found: /favicon.ico
Not Found: /favicon.ico
Not Found: /favicon.ico
[2021-02-25 16:34:03 +0200] [30160] [INFO] Starting gunicorn 20.0.4
[2021-02-25 16:34:03 +0200] [30160] [INFO] Listening at: http://127.0.0.1:8000 (30160)
[2021-02-25 16:34:03 +0200] [30160] [INFO] Using worker: sync
[2021-02-25 16:34:03 +0200] [30163] [INFO] Booting worker with pid: 30163
[2021-02-25 16:34:03 +0200] [30164] [INFO] Booting worker with pid: 30164
[2021-02-25 16:34:03 +0200] [30165] [INFO] Booting worker with pid: 30165
[2021-02-25 14:34:03 +0000] [30163] [ERROR] Exception in worker process
Traceback (most recent call last):
  File "/home/yoga/lib/python3.6/site-packages/gunicorn/arbiter.py", line 583, in spawn_worker
    worker.init_process()
  File "/home/yoga/lib/python3.6/site-packages/gunicorn/workers/base.py", line 119, in init_process
    self.load_wsgi()
  File "/home/yoga/lib/python3.6/site-packages/gunicorn/workers/base.py", line 144, in load_wsgi
    self.wsgi = self.app.wsgi()
  File "/home/yoga/lib/python3.6/site-packages/gunicorn/app/base.py", line 67, in wsgi
    self.callable = self.load()
  File "/home/yoga/lib/python3.6/site-packages/gunicorn/app/wsgiapp.py", line 49, in load
    return self.load_wsgiapp()
  File "/home/yoga/lib/python3.6/site-packages/gunicorn/app/wsgiapp.py", line 39, in load_wsgiapp
    return util.import_app(self.app_uri)
  File "/home/yoga/lib/python3.6/site-packages/gunicorn/util.py", line 358, in import_app
    mod = importlib.import_module(module)
  File "/usr/lib/python3.6/importlib/__init__.py", line 126, in import_module
    return _bootstrap._gcd_import(name[level:], package, level)
  File "<frozen importlib._bootstrap>", line 994, in _gcd_import
  File "<frozen importlib._bootstrap>", line 971, in _find_and_load
  File "<frozen importlib._bootstrap>", line 955, in _find_and_load_unlocked
  File "<frozen importlib._bootstrap>", line 665, in _load_unlocked
  File "<frozen importlib._bootstrap_external>", line 678, in exec_module
  File "<frozen importlib._bootstrap>", line 219, in _call_with_frames_removed
  File "/home/yoga_vue_django/yoga_back/yoga_back/wsgi.py", line 16, in <module>
    application = get_wsgi_application()
  File "/home/yoga/lib/python3.6/site-packages/django/core/wsgi.py", line 12, in get_wsgi_application
    django.setup(set_prefix=False)
  File "/home/yoga/lib/python3.6/site-packages/django/__init__.py", line 24, in setup
    apps.populate(settings.INSTALLED_APPS)
  File "/home/yoga/lib/python3.6/site-packages/django/apps/registry.py", line 122, in populate
    app_config.ready()
  File "/home/yoga/lib/python3.6/site-packages/django/contrib/admin/apps.py", line 24, in ready
    self.module.autodiscover()
  File "/home/yoga/lib/python3.6/site-packages/django/contrib/admin/__init__.py", line 24, in autodiscover
    autodiscover_modules('admin', register_to=site)
  File "/home/yoga/lib/python3.6/site-packages/django/utils/module_loading.py", line 47, in autodiscover_modules
    import_module('%s.%s' % (app_config.name, module_to_search))
  File "/usr/lib/python3.6/importlib/__init__.py", line 126, in import_module
    return _bootstrap._gcd_import(name[level:], package, level)
  File "<frozen importlib._bootstrap>", line 994, in _gcd_import
  File "<frozen importlib._bootstrap>", line 971, in _find_and_load
  File "<frozen importlib._bootstrap>", line 955, in _find_and_load_unlocked
  File "<frozen importlib._bootstrap>", line 665, in _load_unlocked
  File "<frozen importlib._bootstrap_external>", line 674, in exec_module
  File "<frozen importlib._bootstrap_external>", line 781, in get_code
  File "<frozen importlib._bootstrap_external>", line 741, in source_to_code
  File "<frozen importlib._bootstrap>", line 219, in _call_with_frames_removed
  File "/home/yoga_vue_django/yoga_back/user/admin.py", line 2
    <<<<<<< HEAD
     ^
SyntaxError: invalid syntax
[2021-02-25 14:34:03 +0000] [30163] [INFO] Worker exiting (pid: 30163)
[2021-02-25 14:34:03 +0000] [30164] [ERROR] Exception in worker process
Traceback (most recent call last):
  File "/home/yoga/lib/python3.6/site-packages/gunicorn/arbiter.py", line 583, in spawn_worker
    worker.init_process()
  File "/home/yoga/lib/python3.6/site-packages/gunicorn/workers/base.py", line 119, in init_process
    self.load_wsgi()
  File "/home/yoga/lib/python3.6/site-packages/gunicorn/workers/base.py", line 144, in load_wsgi
    self.wsgi = self.app.wsgi()
  File "/home/yoga/lib/python3.6/site-packages/gunicorn/app/base.py", line 67, in wsgi
    self.callable = self.load()
  File "/home/yoga/lib/python3.6/site-packages/gunicorn/app/wsgiapp.py", line 49, in load
    return self.load_wsgiapp()
  File "/home/yoga/lib/python3.6/site-packages/gunicorn/app/wsgiapp.py", line 39, in load_wsgiapp
    return util.import_app(self.app_uri)
  File "/home/yoga/lib/python3.6/site-packages/gunicorn/util.py", line 358, in import_app
    mod = importlib.import_module(module)
  File "/usr/lib/python3.6/importlib/__init__.py", line 126, in import_module
    return _bootstrap._gcd_import(name[level:], package, level)
  File "<frozen importlib._bootstrap>", line 994, in _gcd_import
  File "<frozen importlib._bootstrap>", line 971, in _find_and_load
  File "<frozen importlib._bootstrap>", line 955, in _find_and_load_unlocked
  File "<frozen importlib._bootstrap>", line 665, in _load_unlocked
  File "<frozen importlib._bootstrap_external>", line 678, in exec_module
  File "<frozen importlib._bootstrap>", line 219, in _call_with_frames_removed
  File "/home/yoga_vue_django/yoga_back/yoga_back/wsgi.py", line 16, in <module>
    application = get_wsgi_application()
  File "/home/yoga/lib/python3.6/site-packages/django/core/wsgi.py", line 12, in get_wsgi_application
    django.setup(set_prefix=False)
  File "/home/yoga/lib/python3.6/site-packages/django/__init__.py", line 24, in setup
    apps.populate(settings.INSTALLED_APPS)
  File "/home/yoga/lib/python3.6/site-packages/django/apps/registry.py", line 122, in populate
    app_config.ready()
  File "/home/yoga/lib/python3.6/site-packages/django/contrib/admin/apps.py", line 24, in ready
    self.module.autodiscover()
  File "/home/yoga/lib/python3.6/site-packages/django/contrib/admin/__init__.py", line 24, in autodiscover
    autodiscover_modules('admin', register_to=site)
  File "/home/yoga/lib/python3.6/site-packages/django/utils/module_loading.py", line 47, in autodiscover_modules
    import_module('%s.%s' % (app_config.name, module_to_search))
  File "/usr/lib/python3.6/importlib/__init__.py", line 126, in import_module
    return _bootstrap._gcd_import(name[level:], package, level)
  File "<frozen importlib._bootstrap>", line 994, in _gcd_import
  File "<frozen importlib._bootstrap>", line 971, in _find_and_load
  File "<frozen importlib._bootstrap>", line 955, in _find_and_load_unlocked
  File "<frozen importlib._bootstrap>", line 665, in _load_unlocked
  File "<frozen importlib._bootstrap_external>", line 674, in exec_module
  File "<frozen importlib._bootstrap_external>", line 781, in get_code
  File "<frozen importlib._bootstrap_external>", line 741, in source_to_code
  File "<frozen importlib._bootstrap>", line 219, in _call_with_frames_removed
  File "/home/yoga_vue_django/yoga_back/user/admin.py", line 2
    <<<<<<< HEAD
     ^
SyntaxError: invalid syntax
[2021-02-25 14:34:03 +0000] [30164] [INFO] Worker exiting (pid: 30164)
[2021-02-25 14:34:03 +0000] [30165] [ERROR] Exception in worker process
Traceback (most recent call last):
  File "/home/yoga/lib/python3.6/site-packages/gunicorn/arbiter.py", line 583, in spawn_worker
    worker.init_process()
  File "/home/yoga/lib/python3.6/site-packages/gunicorn/workers/base.py", line 119, in init_process
    self.load_wsgi()
  File "/home/yoga/lib/python3.6/site-packages/gunicorn/workers/base.py", line 144, in load_wsgi
    self.wsgi = self.app.wsgi()
  File "/home/yoga/lib/python3.6/site-packages/gunicorn/app/base.py", line 67, in wsgi
    self.callable = self.load()
  File "/home/yoga/lib/python3.6/site-packages/gunicorn/app/wsgiapp.py", line 49, in load
    return self.load_wsgiapp()
  File "/home/yoga/lib/python3.6/site-packages/gunicorn/app/wsgiapp.py", line 39, in load_wsgiapp
    return util.import_app(self.app_uri)
  File "/home/yoga/lib/python3.6/site-packages/gunicorn/util.py", line 358, in import_app
    mod = importlib.import_module(module)
  File "/usr/lib/python3.6/importlib/__init__.py", line 126, in import_module
    return _bootstrap._gcd_import(name[level:], package, level)
  File "<frozen importlib._bootstrap>", line 994, in _gcd_import
  File "<frozen importlib._bootstrap>", line 971, in _find_and_load
  File "<frozen importlib._bootstrap>", line 955, in _find_and_load_unlocked
  File "<frozen importlib._bootstrap>", line 665, in _load_unlocked
  File "<frozen importlib._bootstrap_external>", line 678, in exec_module
  File "<frozen importlib._bootstrap>", line 219, in _call_with_frames_removed
  File "/home/yoga_vue_django/yoga_back/yoga_back/wsgi.py", line 16, in <module>
    application = get_wsgi_application()
  File "/home/yoga/lib/python3.6/site-packages/django/core/wsgi.py", line 12, in get_wsgi_application
    django.setup(set_prefix=False)
  File "/home/yoga/lib/python3.6/site-packages/django/__init__.py", line 24, in setup
    apps.populate(settings.INSTALLED_APPS)
  File "/home/yoga/lib/python3.6/site-packages/django/apps/registry.py", line 122, in populate
    app_config.ready()
  File "/home/yoga/lib/python3.6/site-packages/django/contrib/admin/apps.py", line 24, in ready
    self.module.autodiscover()
  File "/home/yoga/lib/python3.6/site-packages/django/contrib/admin/__init__.py", line 24, in autodiscover
    autodiscover_modules('admin', register_to=site)
  File "/home/yoga/lib/python3.6/site-packages/django/utils/module_loading.py", line 47, in autodiscover_modules
    import_module('%s.%s' % (app_config.name, module_to_search))
  File "/usr/lib/python3.6/importlib/__init__.py", line 126, in import_module
    return _bootstrap._gcd_import(name[level:], package, level)
  File "<frozen importlib._bootstrap>", line 994, in _gcd_import
  File "<frozen importlib._bootstrap>", line 971, in _find_and_load
  File "<frozen importlib._bootstrap>", line 955, in _find_and_load_unlocked
  File "<frozen importlib._bootstrap>", line 665, in _load_unlocked
  File "<frozen importlib._bootstrap_external>", line 674, in exec_module
  File "<frozen importlib._bootstrap_external>", line 781, in get_code
  File "<frozen importlib._bootstrap_external>", line 741, in source_to_code
  File "<frozen importlib._bootstrap>", line 219, in _call_with_frames_removed
  File "/home/yoga_vue_django/yoga_back/user/admin.py", line 2
    <<<<<<< HEAD
     ^
SyntaxError: invalid syntax
[2021-02-25 14:34:03 +0000] [30165] [INFO] Worker exiting (pid: 30165)
[2021-02-25 16:34:03 +0200] [30160] [INFO] Shutting down: Master
[2021-02-25 16:34:03 +0200] [30160] [INFO] Reason: Worker failed to boot.
[2021-02-25 16:34:04 +0200] [30170] [INFO] Starting gunicorn 20.0.4
[2021-02-25 16:34:04 +0200] [30170] [INFO] Listening at: http://127.0.0.1:8000 (30170)
[2021-02-25 16:34:04 +0200] [30170] [INFO] Using worker: sync
[2021-02-25 16:34:04 +0200] [30174] [INFO] Booting worker with pid: 30174
[2021-02-25 16:34:05 +0200] [30176] [INFO] Booting worker with pid: 30176
[2021-02-25 16:34:05 +0200] [30178] [INFO] Booting worker with pid: 30178
[2021-02-25 14:34:05 +0000] [30174] [ERROR] Exception in worker process
Traceback (most recent call last):
  File "/home/yoga/lib/python3.6/site-packages/gunicorn/arbiter.py", line 583, in spawn_worker
    worker.init_process()
  File "/home/yoga/lib/python3.6/site-packages/gunicorn/workers/base.py", line 119, in init_process
    self.load_wsgi()
  File "/home/yoga/lib/python3.6/site-packages/gunicorn/workers/base.py", line 144, in load_wsgi
    self.wsgi = self.app.wsgi()
  File "/home/yoga/lib/python3.6/site-packages/gunicorn/app/base.py", line 67, in wsgi
    self.callable = self.load()
  File "/home/yoga/lib/python3.6/site-packages/gunicorn/app/wsgiapp.py", line 49, in load
    return self.load_wsgiapp()
  File "/home/yoga/lib/python3.6/site-packages/gunicorn/app/wsgiapp.py", line 39, in load_wsgiapp
    return util.import_app(self.app_uri)
  File "/home/yoga/lib/python3.6/site-packages/gunicorn/util.py", line 358, in import_app
    mod = importlib.import_module(module)
  File "/usr/lib/python3.6/importlib/__init__.py", line 126, in import_module
    return _bootstrap._gcd_import(name[level:], package, level)
  File "<frozen importlib._bootstrap>", line 994, in _gcd_import
  File "<frozen importlib._bootstrap>", line 971, in _find_and_load
  File "<frozen importlib._bootstrap>", line 955, in _find_and_load_unlocked
  File "<frozen importlib._bootstrap>", line 665, in _load_unlocked
  File "<frozen importlib._bootstrap_external>", line 678, in exec_module
  File "<frozen importlib._bootstrap>", line 219, in _call_with_frames_removed
  File "/home/yoga_vue_django/yoga_back/yoga_back/wsgi.py", line 16, in <module>
    application = get_wsgi_application()
  File "/home/yoga/lib/python3.6/site-packages/django/core/wsgi.py", line 12, in get_wsgi_application
    django.setup(set_prefix=False)
  File "/home/yoga/lib/python3.6/site-packages/django/__init__.py", line 24, in setup
    apps.populate(settings.INSTALLED_APPS)
  File "/home/yoga/lib/python3.6/site-packages/django/apps/registry.py", line 122, in populate
    app_config.ready()
  File "/home/yoga/lib/python3.6/site-packages/django/contrib/admin/apps.py", line 24, in ready
    self.module.autodiscover()
  File "/home/yoga/lib/python3.6/site-packages/django/contrib/admin/__init__.py", line 24, in autodiscover
    autodiscover_modules('admin', register_to=site)
  File "/home/yoga/lib/python3.6/site-packages/django/utils/module_loading.py", line 47, in autodiscover_modules
    import_module('%s.%s' % (app_config.name, module_to_search))
  File "/usr/lib/python3.6/importlib/__init__.py", line 126, in import_module
    return _bootstrap._gcd_import(name[level:], package, level)
  File "<frozen importlib._bootstrap>", line 994, in _gcd_import
  File "<frozen importlib._bootstrap>", line 971, in _find_and_load
  File "<frozen importlib._bootstrap>", line 955, in _find_and_load_unlocked
  File "<frozen importlib._bootstrap>", line 665, in _load_unlocked
  File "<frozen importlib._bootstrap_external>", line 674, in exec_module
  File "<frozen importlib._bootstrap_external>", line 781, in get_code
  File "<frozen importlib._bootstrap_external>", line 741, in source_to_code
  File "<frozen importlib._bootstrap>", line 219, in _call_with_frames_removed
  File "/home/yoga_vue_django/yoga_back/user/admin.py", line 2
    <<<<<<< HEAD
     ^
SyntaxError: invalid syntax
[2021-02-25 14:34:05 +0000] [30174] [INFO] Worker exiting (pid: 30174)
[2021-02-25 14:34:05 +0000] [30176] [ERROR] Exception in worker process
Traceback (most recent call last):
  File "/home/yoga/lib/python3.6/site-packages/gunicorn/arbiter.py", line 583, in spawn_worker
    worker.init_process()
  File "/home/yoga/lib/python3.6/site-packages/gunicorn/workers/base.py", line 119, in init_process
    self.load_wsgi()
  File "/home/yoga/lib/python3.6/site-packages/gunicorn/workers/base.py", line 144, in load_wsgi
    self.wsgi = self.app.wsgi()
  File "/home/yoga/lib/python3.6/site-packages/gunicorn/app/base.py", line 67, in wsgi
    self.callable = self.load()
  File "/home/yoga/lib/python3.6/site-packages/gunicorn/app/wsgiapp.py", line 49, in load
    return self.load_wsgiapp()
  File "/home/yoga/lib/python3.6/site-packages/gunicorn/app/wsgiapp.py", line 39, in load_wsgiapp
    return util.import_app(self.app_uri)
  File "/home/yoga/lib/python3.6/site-packages/gunicorn/util.py", line 358, in import_app
    mod = importlib.import_module(module)
  File "/usr/lib/python3.6/importlib/__init__.py", line 126, in import_module
    return _bootstrap._gcd_import(name[level:], package, level)
  File "<frozen importlib._bootstrap>", line 994, in _gcd_import
  File "<frozen importlib._bootstrap>", line 971, in _find_and_load
  File "<frozen importlib._bootstrap>", line 955, in _find_and_load_unlocked
  File "<frozen importlib._bootstrap>", line 665, in _load_unlocked
  File "<frozen importlib._bootstrap_external>", line 678, in exec_module
  File "<frozen importlib._bootstrap>", line 219, in _call_with_frames_removed
  File "/home/yoga_vue_django/yoga_back/yoga_back/wsgi.py", line 16, in <module>
    application = get_wsgi_application()
  File "/home/yoga/lib/python3.6/site-packages/django/core/wsgi.py", line 12, in get_wsgi_application
    django.setup(set_prefix=False)
  File "/home/yoga/lib/python3.6/site-packages/django/__init__.py", line 24, in setup
    apps.populate(settings.INSTALLED_APPS)
  File "/home/yoga/lib/python3.6/site-packages/django/apps/registry.py", line 122, in populate
    app_config.ready()
  File "/home/yoga/lib/python3.6/site-packages/django/contrib/admin/apps.py", line 24, in ready
    self.module.autodiscover()
  File "/home/yoga/lib/python3.6/site-packages/django/contrib/admin/__init__.py", line 24, in autodiscover
    autodiscover_modules('admin', register_to=site)
  File "/home/yoga/lib/python3.6/site-packages/django/utils/module_loading.py", line 47, in autodiscover_modules
    import_module('%s.%s' % (app_config.name, module_to_search))
  File "/usr/lib/python3.6/importlib/__init__.py", line 126, in import_module
    return _bootstrap._gcd_import(name[level:], package, level)
  File "<frozen importlib._bootstrap>", line 994, in _gcd_import
  File "<frozen importlib._bootstrap>", line 971, in _find_and_load
  File "<frozen importlib._bootstrap>", line 955, in _find_and_load_unlocked
  File "<frozen importlib._bootstrap>", line 665, in _load_unlocked
  File "<frozen importlib._bootstrap_external>", line 674, in exec_module
  File "<frozen importlib._bootstrap_external>", line 781, in get_code
  File "<frozen importlib._bootstrap_external>", line 741, in source_to_code
  File "<frozen importlib._bootstrap>", line 219, in _call_with_frames_removed
  File "/home/yoga_vue_django/yoga_back/user/admin.py", line 2
    <<<<<<< HEAD
     ^
SyntaxError: invalid syntax
[2021-02-25 14:34:05 +0000] [30176] [INFO] Worker exiting (pid: 30176)
[2021-02-25 14:34:05 +0000] [30178] [ERROR] Exception in worker process
Traceback (most recent call last):
  File "/home/yoga/lib/python3.6/site-packages/gunicorn/arbiter.py", line 583, in spawn_worker
    worker.init_process()
  File "/home/yoga/lib/python3.6/site-packages/gunicorn/workers/base.py", line 119, in init_process
    self.load_wsgi()
  File "/home/yoga/lib/python3.6/site-packages/gunicorn/workers/base.py", line 144, in load_wsgi
    self.wsgi = self.app.wsgi()
  File "/home/yoga/lib/python3.6/site-packages/gunicorn/app/base.py", line 67, in wsgi
    self.callable = self.load()
  File "/home/yoga/lib/python3.6/site-packages/gunicorn/app/wsgiapp.py", line 49, in load
    return self.load_wsgiapp()
  File "/home/yoga/lib/python3.6/site-packages/gunicorn/app/wsgiapp.py", line 39, in load_wsgiapp
    return util.import_app(self.app_uri)
  File "/home/yoga/lib/python3.6/site-packages/gunicorn/util.py", line 358, in import_app
    mod = importlib.import_module(module)
  File "/usr/lib/python3.6/importlib/__init__.py", line 126, in import_module
    return _bootstrap._gcd_import(name[level:], package, level)
  File "<frozen importlib._bootstrap>", line 994, in _gcd_import
  File "<frozen importlib._bootstrap>", line 971, in _find_and_load
  File "<frozen importlib._bootstrap>", line 955, in _find_and_load_unlocked
  File "<frozen importlib._bootstrap>", line 665, in _load_unlocked
  File "<frozen importlib._bootstrap_external>", line 678, in exec_module
  File "<frozen importlib._bootstrap>", line 219, in _call_with_frames_removed
  File "/home/yoga_vue_django/yoga_back/yoga_back/wsgi.py", line 16, in <module>
    application = get_wsgi_application()
  File "/home/yoga/lib/python3.6/site-packages/django/core/wsgi.py", line 12, in get_wsgi_application
    django.setup(set_prefix=False)
  File "/home/yoga/lib/python3.6/site-packages/django/__init__.py", line 24, in setup
    apps.populate(settings.INSTALLED_APPS)
  File "/home/yoga/lib/python3.6/site-packages/django/apps/registry.py", line 122, in populate
    app_config.ready()
  File "/home/yoga/lib/python3.6/site-packages/django/contrib/admin/apps.py", line 24, in ready
    self.module.autodiscover()
  File "/home/yoga/lib/python3.6/site-packages/django/contrib/admin/__init__.py", line 24, in autodiscover
    autodiscover_modules('admin', register_to=site)
  File "/home/yoga/lib/python3.6/site-packages/django/utils/module_loading.py", line 47, in autodiscover_modules
    import_module('%s.%s' % (app_config.name, module_to_search))
  File "/usr/lib/python3.6/importlib/__init__.py", line 126, in import_module
    return _bootstrap._gcd_import(name[level:], package, level)
  File "<frozen importlib._bootstrap>", line 994, in _gcd_import
  File "<frozen importlib._bootstrap>", line 971, in _find_and_load
  File "<frozen importlib._bootstrap>", line 955, in _find_and_load_unlocked
  File "<frozen importlib._bootstrap>", line 665, in _load_unlocked
  File "<frozen importlib._bootstrap_external>", line 674, in exec_module
  File "<frozen importlib._bootstrap_external>", line 781, in get_code
  File "<frozen importlib._bootstrap_external>", line 741, in source_to_code
  File "<frozen importlib._bootstrap>", line 219, in _call_with_frames_removed
  File "/home/yoga_vue_django/yoga_back/user/admin.py", line 2
    <<<<<<< HEAD
     ^
SyntaxError: invalid syntax
[2021-02-25 14:34:05 +0000] [30178] [INFO] Worker exiting (pid: 30178)
Traceback (most recent call last):
  File "/home/yoga/lib/python3.6/site-packages/gunicorn/arbiter.py", line 209, in run
    self.sleep()
  File "/home/yoga/lib/python3.6/site-packages/gunicorn/arbiter.py", line 357, in sleep
    ready = select.select([self.PIPE[0]], [], [], 1.0)
  File "/home/yoga/lib/python3.6/site-packages/gunicorn/arbiter.py", line 242, in handle_chld
    self.reap_workers()
  File "/home/yoga/lib/python3.6/site-packages/gunicorn/arbiter.py", line 525, in reap_workers
    raise HaltServer(reason, self.WORKER_BOOT_ERROR)
gunicorn.errors.HaltServer: <HaltServer 'Worker failed to boot.' 3>

During handling of the above exception, another exception occurred:

Traceback (most recent call last):
  File "/home/yoga/bin/gunicorn", line 8, in <module>
    sys.exit(run())
  File "/home/yoga/lib/python3.6/site-packages/gunicorn/app/wsgiapp.py", line 58, in run
    WSGIApplication("%(prog)s [OPTIONS] [APP_MODULE]").run()
  File "/home/yoga/lib/python3.6/site-packages/gunicorn/app/base.py", line 228, in run
    super().run()
  File "/home/yoga/lib/python3.6/site-packages/gunicorn/app/base.py", line 72, in run
    Arbiter(self).run()
  File "/home/yoga/lib/python3.6/site-packages/gunicorn/arbiter.py", line 229, in run
    self.halt(reason=inst.reason, exit_status=inst.exit_status)
  File "/home/yoga/lib/python3.6/site-packages/gunicorn/arbiter.py", line 342, in halt
    self.stop()
  File "/home/yoga/lib/python3.6/site-packages/gunicorn/arbiter.py", line 393, in stop
    time.sleep(0.1)
  File "/home/yoga/lib/python3.6/site-packages/gunicorn/arbiter.py", line 242, in handle_chld
    self.reap_workers()
  File "/home/yoga/lib/python3.6/site-packages/gunicorn/arbiter.py", line 525, in reap_workers
    raise HaltServer(reason, self.WORKER_BOOT_ERROR)
gunicorn.errors.HaltServer: <HaltServer 'Worker failed to boot.' 3>
[2021-02-25 16:34:07 +0200] [30181] [INFO] Starting gunicorn 20.0.4
[2021-02-25 16:34:07 +0200] [30181] [INFO] Listening at: http://127.0.0.1:8000 (30181)
[2021-02-25 16:34:07 +0200] [30181] [INFO] Using worker: sync
[2021-02-25 16:34:07 +0200] [30184] [INFO] Booting worker with pid: 30184
[2021-02-25 16:34:07 +0200] [30186] [INFO] Booting worker with pid: 30186
[2021-02-25 16:34:07 +0200] [30188] [INFO] Booting worker with pid: 30188
[2021-02-25 14:34:08 +0000] [30184] [ERROR] Exception in worker process
Traceback (most recent call last):
  File "/home/yoga/lib/python3.6/site-packages/gunicorn/arbiter.py", line 583, in spawn_worker
    worker.init_process()
  File "/home/yoga/lib/python3.6/site-packages/gunicorn/workers/base.py", line 119, in init_process
    self.load_wsgi()
  File "/home/yoga/lib/python3.6/site-packages/gunicorn/workers/base.py", line 144, in load_wsgi
    self.wsgi = self.app.wsgi()
  File "/home/yoga/lib/python3.6/site-packages/gunicorn/app/base.py", line 67, in wsgi
    self.callable = self.load()
  File "/home/yoga/lib/python3.6/site-packages/gunicorn/app/wsgiapp.py", line 49, in load
    return self.load_wsgiapp()
  File "/home/yoga/lib/python3.6/site-packages/gunicorn/app/wsgiapp.py", line 39, in load_wsgiapp
    return util.import_app(self.app_uri)
  File "/home/yoga/lib/python3.6/site-packages/gunicorn/util.py", line 358, in import_app
    mod = importlib.import_module(module)
  File "/usr/lib/python3.6/importlib/__init__.py", line 126, in import_module
    return _bootstrap._gcd_import(name[level:], package, level)
  File "<frozen importlib._bootstrap>", line 994, in _gcd_import
  File "<frozen importlib._bootstrap>", line 971, in _find_and_load
  File "<frozen importlib._bootstrap>", line 955, in _find_and_load_unlocked
  File "<frozen importlib._bootstrap>", line 665, in _load_unlocked
  File "<frozen importlib._bootstrap_external>", line 678, in exec_module
  File "<frozen importlib._bootstrap>", line 219, in _call_with_frames_removed
  File "/home/yoga_vue_django/yoga_back/yoga_back/wsgi.py", line 16, in <module>
    application = get_wsgi_application()
  File "/home/yoga/lib/python3.6/site-packages/django/core/wsgi.py", line 12, in get_wsgi_application
    django.setup(set_prefix=False)
  File "/home/yoga/lib/python3.6/site-packages/django/__init__.py", line 24, in setup
    apps.populate(settings.INSTALLED_APPS)
  File "/home/yoga/lib/python3.6/site-packages/django/apps/registry.py", line 122, in populate
    app_config.ready()
  File "/home/yoga/lib/python3.6/site-packages/django/contrib/admin/apps.py", line 24, in ready
    self.module.autodiscover()
  File "/home/yoga/lib/python3.6/site-packages/django/contrib/admin/__init__.py", line 24, in autodiscover
    autodiscover_modules('admin', register_to=site)
  File "/home/yoga/lib/python3.6/site-packages/django/utils/module_loading.py", line 47, in autodiscover_modules
    import_module('%s.%s' % (app_config.name, module_to_search))
  File "/usr/lib/python3.6/importlib/__init__.py", line 126, in import_module
    return _bootstrap._gcd_import(name[level:], package, level)
  File "<frozen importlib._bootstrap>", line 994, in _gcd_import
  File "<frozen importlib._bootstrap>", line 971, in _find_and_load
  File "<frozen importlib._bootstrap>", line 955, in _find_and_load_unlocked
  File "<frozen importlib._bootstrap>", line 665, in _load_unlocked
  File "<frozen importlib._bootstrap_external>", line 674, in exec_module
  File "<frozen importlib._bootstrap_external>", line 781, in get_code
  File "<frozen importlib._bootstrap_external>", line 741, in source_to_code
  File "<frozen importlib._bootstrap>", line 219, in _call_with_frames_removed
  File "/home/yoga_vue_django/yoga_back/user/admin.py", line 2
    <<<<<<< HEAD
     ^
SyntaxError: invalid syntax
[2021-02-25 14:34:08 +0000] [30184] [INFO] Worker exiting (pid: 30184)
[2021-02-25 14:34:08 +0000] [30186] [ERROR] Exception in worker process
Traceback (most recent call last):
  File "/home/yoga/lib/python3.6/site-packages/gunicorn/arbiter.py", line 583, in spawn_worker
    worker.init_process()
  File "/home/yoga/lib/python3.6/site-packages/gunicorn/workers/base.py", line 119, in init_process
    self.load_wsgi()
  File "/home/yoga/lib/python3.6/site-packages/gunicorn/workers/base.py", line 144, in load_wsgi
    self.wsgi = self.app.wsgi()
  File "/home/yoga/lib/python3.6/site-packages/gunicorn/app/base.py", line 67, in wsgi
    self.callable = self.load()
  File "/home/yoga/lib/python3.6/site-packages/gunicorn/app/wsgiapp.py", line 49, in load
    return self.load_wsgiapp()
  File "/home/yoga/lib/python3.6/site-packages/gunicorn/app/wsgiapp.py", line 39, in load_wsgiapp
    return util.import_app(self.app_uri)
  File "/home/yoga/lib/python3.6/site-packages/gunicorn/util.py", line 358, in import_app
    mod = importlib.import_module(module)
  File "/usr/lib/python3.6/importlib/__init__.py", line 126, in import_module
    return _bootstrap._gcd_import(name[level:], package, level)
  File "<frozen importlib._bootstrap>", line 994, in _gcd_import
  File "<frozen importlib._bootstrap>", line 971, in _find_and_load
  File "<frozen importlib._bootstrap>", line 955, in _find_and_load_unlocked
  File "<frozen importlib._bootstrap>", line 665, in _load_unlocked
  File "<frozen importlib._bootstrap_external>", line 678, in exec_module
  File "<frozen importlib._bootstrap>", line 219, in _call_with_frames_removed
  File "/home/yoga_vue_django/yoga_back/yoga_back/wsgi.py", line 16, in <module>
    application = get_wsgi_application()
  File "/home/yoga/lib/python3.6/site-packages/django/core/wsgi.py", line 12, in get_wsgi_application
    django.setup(set_prefix=False)
  File "/home/yoga/lib/python3.6/site-packages/django/__init__.py", line 24, in setup
    apps.populate(settings.INSTALLED_APPS)
  File "/home/yoga/lib/python3.6/site-packages/django/apps/registry.py", line 122, in populate
    app_config.ready()
  File "/home/yoga/lib/python3.6/site-packages/django/contrib/admin/apps.py", line 24, in ready
    self.module.autodiscover()
  File "/home/yoga/lib/python3.6/site-packages/django/contrib/admin/__init__.py", line 24, in autodiscover
    autodiscover_modules('admin', register_to=site)
  File "/home/yoga/lib/python3.6/site-packages/django/utils/module_loading.py", line 47, in autodiscover_modules
    import_module('%s.%s' % (app_config.name, module_to_search))
  File "/usr/lib/python3.6/importlib/__init__.py", line 126, in import_module
    return _bootstrap._gcd_import(name[level:], package, level)
  File "<frozen importlib._bootstrap>", line 994, in _gcd_import
  File "<frozen importlib._bootstrap>", line 971, in _find_and_load
  File "<frozen importlib._bootstrap>", line 955, in _find_and_load_unlocked
  File "<frozen importlib._bootstrap>", line 665, in _load_unlocked
  File "<frozen importlib._bootstrap_external>", line 674, in exec_module
  File "<frozen importlib._bootstrap_external>", line 781, in get_code
  File "<frozen importlib._bootstrap_external>", line 741, in source_to_code
  File "<frozen importlib._bootstrap>", line 219, in _call_with_frames_removed
  File "/home/yoga_vue_django/yoga_back/user/admin.py", line 2
    <<<<<<< HEAD
     ^
SyntaxError: invalid syntax
[2021-02-25 14:34:08 +0000] [30186] [INFO] Worker exiting (pid: 30186)
[2021-02-25 14:34:08 +0000] [30188] [ERROR] Exception in worker process
Traceback (most recent call last):
  File "/home/yoga/lib/python3.6/site-packages/gunicorn/arbiter.py", line 583, in spawn_worker
    worker.init_process()
  File "/home/yoga/lib/python3.6/site-packages/gunicorn/workers/base.py", line 119, in init_process
    self.load_wsgi()
  File "/home/yoga/lib/python3.6/site-packages/gunicorn/workers/base.py", line 144, in load_wsgi
    self.wsgi = self.app.wsgi()
  File "/home/yoga/lib/python3.6/site-packages/gunicorn/app/base.py", line 67, in wsgi
    self.callable = self.load()
  File "/home/yoga/lib/python3.6/site-packages/gunicorn/app/wsgiapp.py", line 49, in load
    return self.load_wsgiapp()
  File "/home/yoga/lib/python3.6/site-packages/gunicorn/app/wsgiapp.py", line 39, in load_wsgiapp
    return util.import_app(self.app_uri)
  File "/home/yoga/lib/python3.6/site-packages/gunicorn/util.py", line 358, in import_app
    mod = importlib.import_module(module)
  File "/usr/lib/python3.6/importlib/__init__.py", line 126, in import_module
    return _bootstrap._gcd_import(name[level:], package, level)
  File "<frozen importlib._bootstrap>", line 994, in _gcd_import
  File "<frozen importlib._bootstrap>", line 971, in _find_and_load
  File "<frozen importlib._bootstrap>", line 955, in _find_and_load_unlocked
  File "<frozen importlib._bootstrap>", line 665, in _load_unlocked
  File "<frozen importlib._bootstrap_external>", line 678, in exec_module
  File "<frozen importlib._bootstrap>", line 219, in _call_with_frames_removed
  File "/home/yoga_vue_django/yoga_back/yoga_back/wsgi.py", line 16, in <module>
    application = get_wsgi_application()
  File "/home/yoga/lib/python3.6/site-packages/django/core/wsgi.py", line 12, in get_wsgi_application
    django.setup(set_prefix=False)
  File "/home/yoga/lib/python3.6/site-packages/django/__init__.py", line 24, in setup
    apps.populate(settings.INSTALLED_APPS)
  File "/home/yoga/lib/python3.6/site-packages/django/apps/registry.py", line 122, in populate
    app_config.ready()
  File "/home/yoga/lib/python3.6/site-packages/django/contrib/admin/apps.py", line 24, in ready
    self.module.autodiscover()
  File "/home/yoga/lib/python3.6/site-packages/django/contrib/admin/__init__.py", line 24, in autodiscover
    autodiscover_modules('admin', register_to=site)
  File "/home/yoga/lib/python3.6/site-packages/django/utils/module_loading.py", line 47, in autodiscover_modules
    import_module('%s.%s' % (app_config.name, module_to_search))
  File "/usr/lib/python3.6/importlib/__init__.py", line 126, in import_module
    return _bootstrap._gcd_import(name[level:], package, level)
  File "<frozen importlib._bootstrap>", line 994, in _gcd_import
  File "<frozen importlib._bootstrap>", line 971, in _find_and_load
  File "<frozen importlib._bootstrap>", line 955, in _find_and_load_unlocked
  File "<frozen importlib._bootstrap>", line 665, in _load_unlocked
  File "<frozen importlib._bootstrap_external>", line 674, in exec_module
  File "<frozen importlib._bootstrap_external>", line 781, in get_code
  File "<frozen importlib._bootstrap_external>", line 741, in source_to_code
  File "<frozen importlib._bootstrap>", line 219, in _call_with_frames_removed
  File "/home/yoga_vue_django/yoga_back/user/admin.py", line 2
    <<<<<<< HEAD
     ^
SyntaxError: invalid syntax
[2021-02-25 14:34:08 +0000] [30188] [INFO] Worker exiting (pid: 30188)
Traceback (most recent call last):
  File "/home/yoga/lib/python3.6/site-packages/gunicorn/arbiter.py", line 209, in run
    self.sleep()
  File "/home/yoga/lib/python3.6/site-packages/gunicorn/arbiter.py", line 357, in sleep
    ready = select.select([self.PIPE[0]], [], [], 1.0)
  File "/home/yoga/lib/python3.6/site-packages/gunicorn/arbiter.py", line 242, in handle_chld
    self.reap_workers()
  File "/home/yoga/lib/python3.6/site-packages/gunicorn/arbiter.py", line 525, in reap_workers
    raise HaltServer(reason, self.WORKER_BOOT_ERROR)
gunicorn.errors.HaltServer: <HaltServer 'Worker failed to boot.' 3>

During handling of the above exception, another exception occurred:

Traceback (most recent call last):
  File "/home/yoga/bin/gunicorn", line 8, in <module>
    sys.exit(run())
  File "/home/yoga/lib/python3.6/site-packages/gunicorn/app/wsgiapp.py", line 58, in run
    WSGIApplication("%(prog)s [OPTIONS] [APP_MODULE]").run()
  File "/home/yoga/lib/python3.6/site-packages/gunicorn/app/base.py", line 228, in run
    super().run()
  File "/home/yoga/lib/python3.6/site-packages/gunicorn/app/base.py", line 72, in run
    Arbiter(self).run()
  File "/home/yoga/lib/python3.6/site-packages/gunicorn/arbiter.py", line 229, in run
    self.halt(reason=inst.reason, exit_status=inst.exit_status)
  File "/home/yoga/lib/python3.6/site-packages/gunicorn/arbiter.py", line 342, in halt
    self.stop()
  File "/home/yoga/lib/python3.6/site-packages/gunicorn/arbiter.py", line 393, in stop
    time.sleep(0.1)
  File "/home/yoga/lib/python3.6/site-packages/gunicorn/arbiter.py", line 242, in handle_chld
    self.reap_workers()
  File "/home/yoga/lib/python3.6/site-packages/gunicorn/arbiter.py", line 525, in reap_workers
    raise HaltServer(reason, self.WORKER_BOOT_ERROR)
gunicorn.errors.HaltServer: <HaltServer 'Worker failed to boot.' 3>
[2021-02-25 16:34:11 +0200] [30190] [INFO] Starting gunicorn 20.0.4
[2021-02-25 16:34:11 +0200] [30190] [INFO] Listening at: http://127.0.0.1:8000 (30190)
[2021-02-25 16:34:11 +0200] [30190] [INFO] Using worker: sync
[2021-02-25 16:34:11 +0200] [30193] [INFO] Booting worker with pid: 30193
[2021-02-25 16:34:11 +0200] [30195] [INFO] Booting worker with pid: 30195
[2021-02-25 16:34:11 +0200] [30197] [INFO] Booting worker with pid: 30197
[2021-02-25 14:34:11 +0000] [30193] [ERROR] Exception in worker process
Traceback (most recent call last):
  File "/home/yoga/lib/python3.6/site-packages/gunicorn/arbiter.py", line 583, in spawn_worker
    worker.init_process()
  File "/home/yoga/lib/python3.6/site-packages/gunicorn/workers/base.py", line 119, in init_process
    self.load_wsgi()
  File "/home/yoga/lib/python3.6/site-packages/gunicorn/workers/base.py", line 144, in load_wsgi
    self.wsgi = self.app.wsgi()
  File "/home/yoga/lib/python3.6/site-packages/gunicorn/app/base.py", line 67, in wsgi
    self.callable = self.load()
  File "/home/yoga/lib/python3.6/site-packages/gunicorn/app/wsgiapp.py", line 49, in load
    return self.load_wsgiapp()
  File "/home/yoga/lib/python3.6/site-packages/gunicorn/app/wsgiapp.py", line 39, in load_wsgiapp
    return util.import_app(self.app_uri)
  File "/home/yoga/lib/python3.6/site-packages/gunicorn/util.py", line 358, in import_app
    mod = importlib.import_module(module)
  File "/usr/lib/python3.6/importlib/__init__.py", line 126, in import_module
    return _bootstrap._gcd_import(name[level:], package, level)
  File "<frozen importlib._bootstrap>", line 994, in _gcd_import
  File "<frozen importlib._bootstrap>", line 971, in _find_and_load
  File "<frozen importlib._bootstrap>", line 955, in _find_and_load_unlocked
  File "<frozen importlib._bootstrap>", line 665, in _load_unlocked
  File "<frozen importlib._bootstrap_external>", line 678, in exec_module
  File "<frozen importlib._bootstrap>", line 219, in _call_with_frames_removed
  File "/home/yoga_vue_django/yoga_back/yoga_back/wsgi.py", line 16, in <module>
    application = get_wsgi_application()
  File "/home/yoga/lib/python3.6/site-packages/django/core/wsgi.py", line 12, in get_wsgi_application
    django.setup(set_prefix=False)
  File "/home/yoga/lib/python3.6/site-packages/django/__init__.py", line 24, in setup
    apps.populate(settings.INSTALLED_APPS)
  File "/home/yoga/lib/python3.6/site-packages/django/apps/registry.py", line 122, in populate
    app_config.ready()
  File "/home/yoga/lib/python3.6/site-packages/django/contrib/admin/apps.py", line 24, in ready
    self.module.autodiscover()
  File "/home/yoga/lib/python3.6/site-packages/django/contrib/admin/__init__.py", line 24, in autodiscover
    autodiscover_modules('admin', register_to=site)
  File "/home/yoga/lib/python3.6/site-packages/django/utils/module_loading.py", line 47, in autodiscover_modules
    import_module('%s.%s' % (app_config.name, module_to_search))
  File "/usr/lib/python3.6/importlib/__init__.py", line 126, in import_module
    return _bootstrap._gcd_import(name[level:], package, level)
  File "<frozen importlib._bootstrap>", line 994, in _gcd_import
  File "<frozen importlib._bootstrap>", line 971, in _find_and_load
  File "<frozen importlib._bootstrap>", line 955, in _find_and_load_unlocked
  File "<frozen importlib._bootstrap>", line 665, in _load_unlocked
  File "<frozen importlib._bootstrap_external>", line 674, in exec_module
  File "<frozen importlib._bootstrap_external>", line 781, in get_code
  File "<frozen importlib._bootstrap_external>", line 741, in source_to_code
  File "<frozen importlib._bootstrap>", line 219, in _call_with_frames_removed
  File "/home/yoga_vue_django/yoga_back/user/admin.py", line 2
    <<<<<<< HEAD
     ^
SyntaxError: invalid syntax
[2021-02-25 14:34:11 +0000] [30193] [INFO] Worker exiting (pid: 30193)
[2021-02-25 14:34:12 +0000] [30195] [ERROR] Exception in worker process
Traceback (most recent call last):
  File "/home/yoga/lib/python3.6/site-packages/gunicorn/arbiter.py", line 583, in spawn_worker
    worker.init_process()
  File "/home/yoga/lib/python3.6/site-packages/gunicorn/workers/base.py", line 119, in init_process
    self.load_wsgi()
  File "/home/yoga/lib/python3.6/site-packages/gunicorn/workers/base.py", line 144, in load_wsgi
    self.wsgi = self.app.wsgi()
  File "/home/yoga/lib/python3.6/site-packages/gunicorn/app/base.py", line 67, in wsgi
    self.callable = self.load()
  File "/home/yoga/lib/python3.6/site-packages/gunicorn/app/wsgiapp.py", line 49, in load
    return self.load_wsgiapp()
  File "/home/yoga/lib/python3.6/site-packages/gunicorn/app/wsgiapp.py", line 39, in load_wsgiapp
    return util.import_app(self.app_uri)
  File "/home/yoga/lib/python3.6/site-packages/gunicorn/util.py", line 358, in import_app
    mod = importlib.import_module(module)
  File "/usr/lib/python3.6/importlib/__init__.py", line 126, in import_module
    return _bootstrap._gcd_import(name[level:], package, level)
  File "<frozen importlib._bootstrap>", line 994, in _gcd_import
  File "<frozen importlib._bootstrap>", line 971, in _find_and_load
  File "<frozen importlib._bootstrap>", line 955, in _find_and_load_unlocked
  File "<frozen importlib._bootstrap>", line 665, in _load_unlocked
  File "<frozen importlib._bootstrap_external>", line 678, in exec_module
  File "<frozen importlib._bootstrap>", line 219, in _call_with_frames_removed
  File "/home/yoga_vue_django/yoga_back/yoga_back/wsgi.py", line 16, in <module>
    application = get_wsgi_application()
  File "/home/yoga/lib/python3.6/site-packages/django/core/wsgi.py", line 12, in get_wsgi_application
    django.setup(set_prefix=False)
  File "/home/yoga/lib/python3.6/site-packages/django/__init__.py", line 24, in setup
    apps.populate(settings.INSTALLED_APPS)
  File "/home/yoga/lib/python3.6/site-packages/django/apps/registry.py", line 122, in populate
    app_config.ready()
  File "/home/yoga/lib/python3.6/site-packages/django/contrib/admin/apps.py", line 24, in ready
    self.module.autodiscover()
  File "/home/yoga/lib/python3.6/site-packages/django/contrib/admin/__init__.py", line 24, in autodiscover
    autodiscover_modules('admin', register_to=site)
  File "/home/yoga/lib/python3.6/site-packages/django/utils/module_loading.py", line 47, in autodiscover_modules
    import_module('%s.%s' % (app_config.name, module_to_search))
  File "/usr/lib/python3.6/importlib/__init__.py", line 126, in import_module
    return _bootstrap._gcd_import(name[level:], package, level)
  File "<frozen importlib._bootstrap>", line 994, in _gcd_import
  File "<frozen importlib._bootstrap>", line 971, in _find_and_load
  File "<frozen importlib._bootstrap>", line 955, in _find_and_load_unlocked
  File "<frozen importlib._bootstrap>", line 665, in _load_unlocked
  File "<frozen importlib._bootstrap_external>", line 674, in exec_module
  File "<frozen importlib._bootstrap_external>", line 781, in get_code
  File "<frozen importlib._bootstrap_external>", line 741, in source_to_code
  File "<frozen importlib._bootstrap>", line 219, in _call_with_frames_removed
  File "/home/yoga_vue_django/yoga_back/user/admin.py", line 2
    <<<<<<< HEAD
     ^
SyntaxError: invalid syntax
[2021-02-25 14:34:12 +0000] [30195] [INFO] Worker exiting (pid: 30195)
[2021-02-25 14:34:12 +0000] [30197] [ERROR] Exception in worker process
Traceback (most recent call last):
  File "/home/yoga/lib/python3.6/site-packages/gunicorn/arbiter.py", line 583, in spawn_worker
    worker.init_process()
  File "/home/yoga/lib/python3.6/site-packages/gunicorn/workers/base.py", line 119, in init_process
    self.load_wsgi()
  File "/home/yoga/lib/python3.6/site-packages/gunicorn/workers/base.py", line 144, in load_wsgi
    self.wsgi = self.app.wsgi()
  File "/home/yoga/lib/python3.6/site-packages/gunicorn/app/base.py", line 67, in wsgi
    self.callable = self.load()
  File "/home/yoga/lib/python3.6/site-packages/gunicorn/app/wsgiapp.py", line 49, in load
    return self.load_wsgiapp()
  File "/home/yoga/lib/python3.6/site-packages/gunicorn/app/wsgiapp.py", line 39, in load_wsgiapp
    return util.import_app(self.app_uri)
  File "/home/yoga/lib/python3.6/site-packages/gunicorn/util.py", line 358, in import_app
    mod = importlib.import_module(module)
  File "/usr/lib/python3.6/importlib/__init__.py", line 126, in import_module
    return _bootstrap._gcd_import(name[level:], package, level)
  File "<frozen importlib._bootstrap>", line 994, in _gcd_import
  File "<frozen importlib._bootstrap>", line 971, in _find_and_load
  File "<frozen importlib._bootstrap>", line 955, in _find_and_load_unlocked
  File "<frozen importlib._bootstrap>", line 665, in _load_unlocked
  File "<frozen importlib._bootstrap_external>", line 678, in exec_module
  File "<frozen importlib._bootstrap>", line 219, in _call_with_frames_removed
  File "/home/yoga_vue_django/yoga_back/yoga_back/wsgi.py", line 16, in <module>
    application = get_wsgi_application()
  File "/home/yoga/lib/python3.6/site-packages/django/core/wsgi.py", line 12, in get_wsgi_application
    django.setup(set_prefix=False)
  File "/home/yoga/lib/python3.6/site-packages/django/__init__.py", line 24, in setup
    apps.populate(settings.INSTALLED_APPS)
  File "/home/yoga/lib/python3.6/site-packages/django/apps/registry.py", line 122, in populate
    app_config.ready()
  File "/home/yoga/lib/python3.6/site-packages/django/contrib/admin/apps.py", line 24, in ready
    self.module.autodiscover()
  File "/home/yoga/lib/python3.6/site-packages/django/contrib/admin/__init__.py", line 24, in autodiscover
    autodiscover_modules('admin', register_to=site)
  File "/home/yoga/lib/python3.6/site-packages/django/utils/module_loading.py", line 47, in autodiscover_modules
    import_module('%s.%s' % (app_config.name, module_to_search))
  File "/usr/lib/python3.6/importlib/__init__.py", line 126, in import_module
    return _bootstrap._gcd_import(name[level:], package, level)
  File "<frozen importlib._bootstrap>", line 994, in _gcd_import
  File "<frozen importlib._bootstrap>", line 971, in _find_and_load
  File "<frozen importlib._bootstrap>", line 955, in _find_and_load_unlocked
  File "<frozen importlib._bootstrap>", line 665, in _load_unlocked
  File "<frozen importlib._bootstrap_external>", line 674, in exec_module
  File "<frozen importlib._bootstrap_external>", line 781, in get_code
  File "<frozen importlib._bootstrap_external>", line 741, in source_to_code
  File "<frozen importlib._bootstrap>", line 219, in _call_with_frames_removed
  File "/home/yoga_vue_django/yoga_back/user/admin.py", line 2
    <<<<<<< HEAD
     ^
SyntaxError: invalid syntax
[2021-02-25 14:34:12 +0000] [30197] [INFO] Worker exiting (pid: 30197)
Traceback (most recent call last):
  File "/home/yoga/lib/python3.6/site-packages/gunicorn/arbiter.py", line 209, in run
    self.sleep()
  File "/home/yoga/lib/python3.6/site-packages/gunicorn/arbiter.py", line 357, in sleep
    ready = select.select([self.PIPE[0]], [], [], 1.0)
  File "/home/yoga/lib/python3.6/site-packages/gunicorn/arbiter.py", line 242, in handle_chld
    self.reap_workers()
  File "/home/yoga/lib/python3.6/site-packages/gunicorn/arbiter.py", line 525, in reap_workers
    raise HaltServer(reason, self.WORKER_BOOT_ERROR)
gunicorn.errors.HaltServer: <HaltServer 'Worker failed to boot.' 3>

During handling of the above exception, another exception occurred:

Traceback (most recent call last):
  File "/home/yoga/bin/gunicorn", line 8, in <module>
    sys.exit(run())
  File "/home/yoga/lib/python3.6/site-packages/gunicorn/app/wsgiapp.py", line 58, in run
    WSGIApplication("%(prog)s [OPTIONS] [APP_MODULE]").run()
  File "/home/yoga/lib/python3.6/site-packages/gunicorn/app/base.py", line 228, in run
    super().run()
  File "/home/yoga/lib/python3.6/site-packages/gunicorn/app/base.py", line 72, in run
    Arbiter(self).run()
  File "/home/yoga/lib/python3.6/site-packages/gunicorn/arbiter.py", line 229, in run
    self.halt(reason=inst.reason, exit_status=inst.exit_status)
  File "/home/yoga/lib/python3.6/site-packages/gunicorn/arbiter.py", line 342, in halt
    self.stop()
  File "/home/yoga/lib/python3.6/site-packages/gunicorn/arbiter.py", line 393, in stop
    time.sleep(0.1)
  File "/home/yoga/lib/python3.6/site-packages/gunicorn/arbiter.py", line 242, in handle_chld
    self.reap_workers()
  File "/home/yoga/lib/python3.6/site-packages/gunicorn/arbiter.py", line 525, in reap_workers
    raise HaltServer(reason, self.WORKER_BOOT_ERROR)
gunicorn.errors.HaltServer: <HaltServer 'Worker failed to boot.' 3>
[2021-02-25 16:35:40 +0200] [30237] [INFO] Starting gunicorn 20.0.4
[2021-02-25 16:35:40 +0200] [30237] [INFO] Listening at: http://127.0.0.1:8000 (30237)
[2021-02-25 16:35:40 +0200] [30237] [INFO] Using worker: sync
[2021-02-25 16:35:40 +0200] [30240] [INFO] Booting worker with pid: 30240
[2021-02-25 16:35:40 +0200] [30242] [INFO] Booting worker with pid: 30242
[2021-02-25 16:35:40 +0200] [30243] [INFO] Booting worker with pid: 30243
Internal Server Error: /admin/user/admin/1/change/
Traceback (most recent call last):
  File "/home/yoga/lib/python3.6/site-packages/django/core/handlers/exception.py", line 47, in inner
    response = get_response(request)
  File "/home/yoga/lib/python3.6/site-packages/django/core/handlers/base.py", line 167, in _get_response
    callback, callback_args, callback_kwargs = self.resolve_request(request)
  File "/home/yoga/lib/python3.6/site-packages/django/core/handlers/base.py", line 290, in resolve_request
    resolver_match = resolver.resolve(request.path_info)
  File "/home/yoga/lib/python3.6/site-packages/django/urls/resolvers.py", line 545, in resolve
    for pattern in self.url_patterns:
  File "/home/yoga/lib/python3.6/site-packages/django/utils/functional.py", line 48, in __get__
    res = instance.__dict__[self.name] = self.func(instance)
  File "/home/yoga/lib/python3.6/site-packages/django/urls/resolvers.py", line 589, in url_patterns
    patterns = getattr(self.urlconf_module, "urlpatterns", self.urlconf_module)
  File "/home/yoga/lib/python3.6/site-packages/django/utils/functional.py", line 48, in __get__
    res = instance.__dict__[self.name] = self.func(instance)
  File "/home/yoga/lib/python3.6/site-packages/django/urls/resolvers.py", line 582, in urlconf_module
    return import_module(self.urlconf_name)
  File "/usr/lib/python3.6/importlib/__init__.py", line 126, in import_module
    return _bootstrap._gcd_import(name[level:], package, level)
  File "<frozen importlib._bootstrap>", line 994, in _gcd_import
  File "<frozen importlib._bootstrap>", line 971, in _find_and_load
  File "<frozen importlib._bootstrap>", line 955, in _find_and_load_unlocked
  File "<frozen importlib._bootstrap>", line 665, in _load_unlocked
  File "<frozen importlib._bootstrap_external>", line 678, in exec_module
  File "<frozen importlib._bootstrap>", line 219, in _call_with_frames_removed
  File "/home/yoga_vue_django/yoga_back/yoga_back/urls.py", line 27, in <module>
    path('api/user/', include('user.urls')),
  File "/home/yoga/lib/python3.6/site-packages/django/urls/conf.py", line 34, in include
    urlconf_module = import_module(urlconf_module)
  File "/usr/lib/python3.6/importlib/__init__.py", line 126, in import_module
    return _bootstrap._gcd_import(name[level:], package, level)
  File "<frozen importlib._bootstrap>", line 994, in _gcd_import
  File "<frozen importlib._bootstrap>", line 971, in _find_and_load
  File "<frozen importlib._bootstrap>", line 955, in _find_and_load_unlocked
  File "<frozen importlib._bootstrap>", line 665, in _load_unlocked
  File "<frozen importlib._bootstrap_external>", line 678, in exec_module
  File "<frozen importlib._bootstrap>", line 219, in _call_with_frames_removed
  File "/home/yoga_vue_django/yoga_back/user/urls.py", line 3, in <module>
    from .views import *
  File "/home/yoga_vue_django/yoga_back/user/views.py", line 92
    <<<<<<< HEAD
     ^
IndentationError: expected an indented block
Internal Server Error: /favicon.ico
Traceback (most recent call last):
  File "/home/yoga/lib/python3.6/site-packages/django/core/handlers/exception.py", line 47, in inner
    response = get_response(request)
  File "/home/yoga/lib/python3.6/site-packages/django/utils/deprecation.py", line 113, in __call__
    response = self.process_request(request)
  File "/home/yoga/lib/python3.6/site-packages/django/middleware/common.py", line 53, in process_request
    if self.should_redirect_with_slash(request):
  File "/home/yoga/lib/python3.6/site-packages/django/middleware/common.py", line 71, in should_redirect_with_slash
    not is_valid_path(request.path_info, urlconf) and
  File "/home/yoga/lib/python3.6/site-packages/django/urls/base.py", line 154, in is_valid_path
    resolve(path, urlconf)
  File "/home/yoga/lib/python3.6/site-packages/django/urls/base.py", line 25, in resolve
    return get_resolver(urlconf).resolve(path)
  File "/home/yoga/lib/python3.6/site-packages/django/urls/resolvers.py", line 545, in resolve
    for pattern in self.url_patterns:
  File "/home/yoga/lib/python3.6/site-packages/django/utils/functional.py", line 48, in __get__
    res = instance.__dict__[self.name] = self.func(instance)
  File "/home/yoga/lib/python3.6/site-packages/django/urls/resolvers.py", line 589, in url_patterns
    patterns = getattr(self.urlconf_module, "urlpatterns", self.urlconf_module)
  File "/home/yoga/lib/python3.6/site-packages/django/utils/functional.py", line 48, in __get__
    res = instance.__dict__[self.name] = self.func(instance)
  File "/home/yoga/lib/python3.6/site-packages/django/urls/resolvers.py", line 582, in urlconf_module
    return import_module(self.urlconf_name)
  File "/usr/lib/python3.6/importlib/__init__.py", line 126, in import_module
    return _bootstrap._gcd_import(name[level:], package, level)
  File "<frozen importlib._bootstrap>", line 994, in _gcd_import
  File "<frozen importlib._bootstrap>", line 971, in _find_and_load
  File "<frozen importlib._bootstrap>", line 955, in _find_and_load_unlocked
  File "<frozen importlib._bootstrap>", line 665, in _load_unlocked
  File "<frozen importlib._bootstrap_external>", line 678, in exec_module
  File "<frozen importlib._bootstrap>", line 219, in _call_with_frames_removed
  File "/home/yoga_vue_django/yoga_back/yoga_back/urls.py", line 27, in <module>
    path('api/user/', include('user.urls')),
  File "/home/yoga/lib/python3.6/site-packages/django/urls/conf.py", line 34, in include
    urlconf_module = import_module(urlconf_module)
  File "/usr/lib/python3.6/importlib/__init__.py", line 126, in import_module
    return _bootstrap._gcd_import(name[level:], package, level)
  File "<frozen importlib._bootstrap>", line 994, in _gcd_import
  File "<frozen importlib._bootstrap>", line 971, in _find_and_load
  File "<frozen importlib._bootstrap>", line 955, in _find_and_load_unlocked
  File "<frozen importlib._bootstrap>", line 665, in _load_unlocked
  File "<frozen importlib._bootstrap_external>", line 678, in exec_module
  File "<frozen importlib._bootstrap>", line 219, in _call_with_frames_removed
  File "/home/yoga_vue_django/yoga_back/user/urls.py", line 3, in <module>
    from .views import *
  File "/home/yoga_vue_django/yoga_back/user/views.py", line 92
    <<<<<<< HEAD
     ^
IndentationError: expected an indented block
Internal Server Error: /admin/user/admin/
Traceback (most recent call last):
  File "/home/yoga/lib/python3.6/site-packages/django/core/handlers/exception.py", line 47, in inner
    response = get_response(request)
  File "/home/yoga/lib/python3.6/site-packages/django/core/handlers/base.py", line 167, in _get_response
    callback, callback_args, callback_kwargs = self.resolve_request(request)
  File "/home/yoga/lib/python3.6/site-packages/django/core/handlers/base.py", line 290, in resolve_request
    resolver_match = resolver.resolve(request.path_info)
  File "/home/yoga/lib/python3.6/site-packages/django/urls/resolvers.py", line 545, in resolve
    for pattern in self.url_patterns:
  File "/home/yoga/lib/python3.6/site-packages/django/utils/functional.py", line 48, in __get__
    res = instance.__dict__[self.name] = self.func(instance)
  File "/home/yoga/lib/python3.6/site-packages/django/urls/resolvers.py", line 589, in url_patterns
    patterns = getattr(self.urlconf_module, "urlpatterns", self.urlconf_module)
  File "/home/yoga/lib/python3.6/site-packages/django/utils/functional.py", line 48, in __get__
    res = instance.__dict__[self.name] = self.func(instance)
  File "/home/yoga/lib/python3.6/site-packages/django/urls/resolvers.py", line 582, in urlconf_module
    return import_module(self.urlconf_name)
  File "/usr/lib/python3.6/importlib/__init__.py", line 126, in import_module
    return _bootstrap._gcd_import(name[level:], package, level)
  File "<frozen importlib._bootstrap>", line 994, in _gcd_import
  File "<frozen importlib._bootstrap>", line 971, in _find_and_load
  File "<frozen importlib._bootstrap>", line 955, in _find_and_load_unlocked
  File "<frozen importlib._bootstrap>", line 665, in _load_unlocked
  File "<frozen importlib._bootstrap_external>", line 678, in exec_module
  File "<frozen importlib._bootstrap>", line 219, in _call_with_frames_removed
  File "/home/yoga_vue_django/yoga_back/yoga_back/urls.py", line 27, in <module>
    path('api/user/', include('user.urls')),
  File "/home/yoga/lib/python3.6/site-packages/django/urls/conf.py", line 34, in include
    urlconf_module = import_module(urlconf_module)
  File "/usr/lib/python3.6/importlib/__init__.py", line 126, in import_module
    return _bootstrap._gcd_import(name[level:], package, level)
  File "<frozen importlib._bootstrap>", line 994, in _gcd_import
  File "<frozen importlib._bootstrap>", line 971, in _find_and_load
  File "<frozen importlib._bootstrap>", line 955, in _find_and_load_unlocked
  File "<frozen importlib._bootstrap>", line 665, in _load_unlocked
  File "<frozen importlib._bootstrap_external>", line 678, in exec_module
  File "<frozen importlib._bootstrap>", line 219, in _call_with_frames_removed
  File "/home/yoga_vue_django/yoga_back/user/urls.py", line 3, in <module>
    from .views import *
  File "/home/yoga_vue_django/yoga_back/user/views.py", line 92
    <<<<<<< HEAD
     ^
IndentationError: expected an indented block
Internal Server Error: /favicon.ico
Traceback (most recent call last):
  File "/home/yoga/lib/python3.6/site-packages/django/core/handlers/exception.py", line 47, in inner
    response = get_response(request)
  File "/home/yoga/lib/python3.6/site-packages/django/utils/deprecation.py", line 113, in __call__
    response = self.process_request(request)
  File "/home/yoga/lib/python3.6/site-packages/django/middleware/common.py", line 53, in process_request
    if self.should_redirect_with_slash(request):
  File "/home/yoga/lib/python3.6/site-packages/django/middleware/common.py", line 71, in should_redirect_with_slash
    not is_valid_path(request.path_info, urlconf) and
  File "/home/yoga/lib/python3.6/site-packages/django/urls/base.py", line 154, in is_valid_path
    resolve(path, urlconf)
  File "/home/yoga/lib/python3.6/site-packages/django/urls/base.py", line 25, in resolve
    return get_resolver(urlconf).resolve(path)
  File "/home/yoga/lib/python3.6/site-packages/django/urls/resolvers.py", line 545, in resolve
    for pattern in self.url_patterns:
  File "/home/yoga/lib/python3.6/site-packages/django/utils/functional.py", line 48, in __get__
    res = instance.__dict__[self.name] = self.func(instance)
  File "/home/yoga/lib/python3.6/site-packages/django/urls/resolvers.py", line 589, in url_patterns
    patterns = getattr(self.urlconf_module, "urlpatterns", self.urlconf_module)
  File "/home/yoga/lib/python3.6/site-packages/django/utils/functional.py", line 48, in __get__
    res = instance.__dict__[self.name] = self.func(instance)
  File "/home/yoga/lib/python3.6/site-packages/django/urls/resolvers.py", line 582, in urlconf_module
    return import_module(self.urlconf_name)
  File "/usr/lib/python3.6/importlib/__init__.py", line 126, in import_module
    return _bootstrap._gcd_import(name[level:], package, level)
  File "<frozen importlib._bootstrap>", line 994, in _gcd_import
  File "<frozen importlib._bootstrap>", line 971, in _find_and_load
  File "<frozen importlib._bootstrap>", line 955, in _find_and_load_unlocked
  File "<frozen importlib._bootstrap>", line 665, in _load_unlocked
  File "<frozen importlib._bootstrap_external>", line 678, in exec_module
  File "<frozen importlib._bootstrap>", line 219, in _call_with_frames_removed
  File "/home/yoga_vue_django/yoga_back/yoga_back/urls.py", line 27, in <module>
    path('api/user/', include('user.urls')),
  File "/home/yoga/lib/python3.6/site-packages/django/urls/conf.py", line 34, in include
    urlconf_module = import_module(urlconf_module)
  File "/usr/lib/python3.6/importlib/__init__.py", line 126, in import_module
    return _bootstrap._gcd_import(name[level:], package, level)
  File "<frozen importlib._bootstrap>", line 994, in _gcd_import
  File "<frozen importlib._bootstrap>", line 971, in _find_and_load
  File "<frozen importlib._bootstrap>", line 955, in _find_and_load_unlocked
  File "<frozen importlib._bootstrap>", line 665, in _load_unlocked
  File "<frozen importlib._bootstrap_external>", line 678, in exec_module
  File "<frozen importlib._bootstrap>", line 219, in _call_with_frames_removed
  File "/home/yoga_vue_django/yoga_back/user/urls.py", line 3, in <module>
    from .views import *
  File "/home/yoga_vue_django/yoga_back/user/views.py", line 92
    <<<<<<< HEAD
     ^
IndentationError: expected an indented block
Internal Server Error: /admin/user/
Traceback (most recent call last):
  File "/home/yoga/lib/python3.6/site-packages/django/core/handlers/exception.py", line 47, in inner
    response = get_response(request)
  File "/home/yoga/lib/python3.6/site-packages/django/core/handlers/base.py", line 167, in _get_response
    callback, callback_args, callback_kwargs = self.resolve_request(request)
  File "/home/yoga/lib/python3.6/site-packages/django/core/handlers/base.py", line 290, in resolve_request
    resolver_match = resolver.resolve(request.path_info)
  File "/home/yoga/lib/python3.6/site-packages/django/urls/resolvers.py", line 545, in resolve
    for pattern in self.url_patterns:
  File "/home/yoga/lib/python3.6/site-packages/django/utils/functional.py", line 48, in __get__
    res = instance.__dict__[self.name] = self.func(instance)
  File "/home/yoga/lib/python3.6/site-packages/django/urls/resolvers.py", line 589, in url_patterns
    patterns = getattr(self.urlconf_module, "urlpatterns", self.urlconf_module)
  File "/home/yoga/lib/python3.6/site-packages/django/utils/functional.py", line 48, in __get__
    res = instance.__dict__[self.name] = self.func(instance)
  File "/home/yoga/lib/python3.6/site-packages/django/urls/resolvers.py", line 582, in urlconf_module
    return import_module(self.urlconf_name)
  File "/usr/lib/python3.6/importlib/__init__.py", line 126, in import_module
    return _bootstrap._gcd_import(name[level:], package, level)
  File "<frozen importlib._bootstrap>", line 994, in _gcd_import
  File "<frozen importlib._bootstrap>", line 971, in _find_and_load
  File "<frozen importlib._bootstrap>", line 955, in _find_and_load_unlocked
  File "<frozen importlib._bootstrap>", line 665, in _load_unlocked
  File "<frozen importlib._bootstrap_external>", line 678, in exec_module
  File "<frozen importlib._bootstrap>", line 219, in _call_with_frames_removed
  File "/home/yoga_vue_django/yoga_back/yoga_back/urls.py", line 27, in <module>
    path('api/user/', include('user.urls')),
  File "/home/yoga/lib/python3.6/site-packages/django/urls/conf.py", line 34, in include
    urlconf_module = import_module(urlconf_module)
  File "/usr/lib/python3.6/importlib/__init__.py", line 126, in import_module
    return _bootstrap._gcd_import(name[level:], package, level)
  File "<frozen importlib._bootstrap>", line 994, in _gcd_import
  File "<frozen importlib._bootstrap>", line 971, in _find_and_load
  File "<frozen importlib._bootstrap>", line 955, in _find_and_load_unlocked
  File "<frozen importlib._bootstrap>", line 665, in _load_unlocked
  File "<frozen importlib._bootstrap_external>", line 678, in exec_module
  File "<frozen importlib._bootstrap>", line 219, in _call_with_frames_removed
  File "/home/yoga_vue_django/yoga_back/user/urls.py", line 3, in <module>
    from .views import *
  File "/home/yoga_vue_django/yoga_back/user/views.py", line 92
    <<<<<<< HEAD
     ^
IndentationError: expected an indented block
Internal Server Error: /favicon.ico
Traceback (most recent call last):
  File "/home/yoga/lib/python3.6/site-packages/django/core/handlers/exception.py", line 47, in inner
    response = get_response(request)
  File "/home/yoga/lib/python3.6/site-packages/django/utils/deprecation.py", line 113, in __call__
    response = self.process_request(request)
  File "/home/yoga/lib/python3.6/site-packages/django/middleware/common.py", line 53, in process_request
    if self.should_redirect_with_slash(request):
  File "/home/yoga/lib/python3.6/site-packages/django/middleware/common.py", line 71, in should_redirect_with_slash
    not is_valid_path(request.path_info, urlconf) and
  File "/home/yoga/lib/python3.6/site-packages/django/urls/base.py", line 154, in is_valid_path
    resolve(path, urlconf)
  File "/home/yoga/lib/python3.6/site-packages/django/urls/base.py", line 25, in resolve
    return get_resolver(urlconf).resolve(path)
  File "/home/yoga/lib/python3.6/site-packages/django/urls/resolvers.py", line 545, in resolve
    for pattern in self.url_patterns:
  File "/home/yoga/lib/python3.6/site-packages/django/utils/functional.py", line 48, in __get__
    res = instance.__dict__[self.name] = self.func(instance)
  File "/home/yoga/lib/python3.6/site-packages/django/urls/resolvers.py", line 589, in url_patterns
    patterns = getattr(self.urlconf_module, "urlpatterns", self.urlconf_module)
  File "/home/yoga/lib/python3.6/site-packages/django/utils/functional.py", line 48, in __get__
    res = instance.__dict__[self.name] = self.func(instance)
  File "/home/yoga/lib/python3.6/site-packages/django/urls/resolvers.py", line 582, in urlconf_module
    return import_module(self.urlconf_name)
  File "/usr/lib/python3.6/importlib/__init__.py", line 126, in import_module
    return _bootstrap._gcd_import(name[level:], package, level)
  File "<frozen importlib._bootstrap>", line 994, in _gcd_import
  File "<frozen importlib._bootstrap>", line 971, in _find_and_load
  File "<frozen importlib._bootstrap>", line 955, in _find_and_load_unlocked
  File "<frozen importlib._bootstrap>", line 665, in _load_unlocked
  File "<frozen importlib._bootstrap_external>", line 678, in exec_module
  File "<frozen importlib._bootstrap>", line 219, in _call_with_frames_removed
  File "/home/yoga_vue_django/yoga_back/yoga_back/urls.py", line 27, in <module>
    path('api/user/', include('user.urls')),
  File "/home/yoga/lib/python3.6/site-packages/django/urls/conf.py", line 34, in include
    urlconf_module = import_module(urlconf_module)
  File "/usr/lib/python3.6/importlib/__init__.py", line 126, in import_module
    return _bootstrap._gcd_import(name[level:], package, level)
  File "<frozen importlib._bootstrap>", line 994, in _gcd_import
  File "<frozen importlib._bootstrap>", line 971, in _find_and_load
  File "<frozen importlib._bootstrap>", line 955, in _find_and_load_unlocked
  File "<frozen importlib._bootstrap>", line 665, in _load_unlocked
  File "<frozen importlib._bootstrap_external>", line 678, in exec_module
  File "<frozen importlib._bootstrap>", line 219, in _call_with_frames_removed
  File "/home/yoga_vue_django/yoga_back/user/urls.py", line 3, in <module>
    from .views import *
  File "/home/yoga_vue_django/yoga_back/user/views.py", line 92
    <<<<<<< HEAD
     ^
IndentationError: expected an indented block
Internal Server Error: /admin/
Traceback (most recent call last):
  File "/home/yoga/lib/python3.6/site-packages/django/core/handlers/exception.py", line 47, in inner
    response = get_response(request)
  File "/home/yoga/lib/python3.6/site-packages/django/core/handlers/base.py", line 167, in _get_response
    callback, callback_args, callback_kwargs = self.resolve_request(request)
  File "/home/yoga/lib/python3.6/site-packages/django/core/handlers/base.py", line 290, in resolve_request
    resolver_match = resolver.resolve(request.path_info)
  File "/home/yoga/lib/python3.6/site-packages/django/urls/resolvers.py", line 545, in resolve
    for pattern in self.url_patterns:
  File "/home/yoga/lib/python3.6/site-packages/django/utils/functional.py", line 48, in __get__
    res = instance.__dict__[self.name] = self.func(instance)
  File "/home/yoga/lib/python3.6/site-packages/django/urls/resolvers.py", line 589, in url_patterns
    patterns = getattr(self.urlconf_module, "urlpatterns", self.urlconf_module)
  File "/home/yoga/lib/python3.6/site-packages/django/utils/functional.py", line 48, in __get__
    res = instance.__dict__[self.name] = self.func(instance)
  File "/home/yoga/lib/python3.6/site-packages/django/urls/resolvers.py", line 582, in urlconf_module
    return import_module(self.urlconf_name)
  File "/usr/lib/python3.6/importlib/__init__.py", line 126, in import_module
    return _bootstrap._gcd_import(name[level:], package, level)
  File "<frozen importlib._bootstrap>", line 994, in _gcd_import
  File "<frozen importlib._bootstrap>", line 971, in _find_and_load
  File "<frozen importlib._bootstrap>", line 955, in _find_and_load_unlocked
  File "<frozen importlib._bootstrap>", line 665, in _load_unlocked
  File "<frozen importlib._bootstrap_external>", line 678, in exec_module
  File "<frozen importlib._bootstrap>", line 219, in _call_with_frames_removed
  File "/home/yoga_vue_django/yoga_back/yoga_back/urls.py", line 27, in <module>
    path('api/user/', include('user.urls')),
  File "/home/yoga/lib/python3.6/site-packages/django/urls/conf.py", line 34, in include
    urlconf_module = import_module(urlconf_module)
  File "/usr/lib/python3.6/importlib/__init__.py", line 126, in import_module
    return _bootstrap._gcd_import(name[level:], package, level)
  File "<frozen importlib._bootstrap>", line 994, in _gcd_import
  File "<frozen importlib._bootstrap>", line 971, in _find_and_load
  File "<frozen importlib._bootstrap>", line 955, in _find_and_load_unlocked
  File "<frozen importlib._bootstrap>", line 665, in _load_unlocked
  File "<frozen importlib._bootstrap_external>", line 678, in exec_module
  File "<frozen importlib._bootstrap>", line 219, in _call_with_frames_removed
  File "/home/yoga_vue_django/yoga_back/user/urls.py", line 3, in <module>
    from .views import *
  File "/home/yoga_vue_django/yoga_back/user/views.py", line 92
    <<<<<<< HEAD
     ^
IndentationError: expected an indented block
Internal Server Error: /favicon.ico
Traceback (most recent call last):
  File "/home/yoga/lib/python3.6/site-packages/django/core/handlers/exception.py", line 47, in inner
    response = get_response(request)
  File "/home/yoga/lib/python3.6/site-packages/django/utils/deprecation.py", line 113, in __call__
    response = self.process_request(request)
  File "/home/yoga/lib/python3.6/site-packages/django/middleware/common.py", line 53, in process_request
    if self.should_redirect_with_slash(request):
  File "/home/yoga/lib/python3.6/site-packages/django/middleware/common.py", line 71, in should_redirect_with_slash
    not is_valid_path(request.path_info, urlconf) and
  File "/home/yoga/lib/python3.6/site-packages/django/urls/base.py", line 154, in is_valid_path
    resolve(path, urlconf)
  File "/home/yoga/lib/python3.6/site-packages/django/urls/base.py", line 25, in resolve
    return get_resolver(urlconf).resolve(path)
  File "/home/yoga/lib/python3.6/site-packages/django/urls/resolvers.py", line 545, in resolve
    for pattern in self.url_patterns:
  File "/home/yoga/lib/python3.6/site-packages/django/utils/functional.py", line 48, in __get__
    res = instance.__dict__[self.name] = self.func(instance)
  File "/home/yoga/lib/python3.6/site-packages/django/urls/resolvers.py", line 589, in url_patterns
    patterns = getattr(self.urlconf_module, "urlpatterns", self.urlconf_module)
  File "/home/yoga/lib/python3.6/site-packages/django/utils/functional.py", line 48, in __get__
    res = instance.__dict__[self.name] = self.func(instance)
  File "/home/yoga/lib/python3.6/site-packages/django/urls/resolvers.py", line 582, in urlconf_module
    return import_module(self.urlconf_name)
  File "/usr/lib/python3.6/importlib/__init__.py", line 126, in import_module
    return _bootstrap._gcd_import(name[level:], package, level)
  File "<frozen importlib._bootstrap>", line 994, in _gcd_import
  File "<frozen importlib._bootstrap>", line 971, in _find_and_load
  File "<frozen importlib._bootstrap>", line 955, in _find_and_load_unlocked
  File "<frozen importlib._bootstrap>", line 665, in _load_unlocked
  File "<frozen importlib._bootstrap_external>", line 678, in exec_module
  File "<frozen importlib._bootstrap>", line 219, in _call_with_frames_removed
  File "/home/yoga_vue_django/yoga_back/yoga_back/urls.py", line 27, in <module>
    path('api/user/', include('user.urls')),
  File "/home/yoga/lib/python3.6/site-packages/django/urls/conf.py", line 34, in include
    urlconf_module = import_module(urlconf_module)
  File "/usr/lib/python3.6/importlib/__init__.py", line 126, in import_module
    return _bootstrap._gcd_import(name[level:], package, level)
  File "<frozen importlib._bootstrap>", line 994, in _gcd_import
  File "<frozen importlib._bootstrap>", line 971, in _find_and_load
  File "<frozen importlib._bootstrap>", line 955, in _find_and_load_unlocked
  File "<frozen importlib._bootstrap>", line 665, in _load_unlocked
  File "<frozen importlib._bootstrap_external>", line 678, in exec_module
  File "<frozen importlib._bootstrap>", line 219, in _call_with_frames_removed
  File "/home/yoga_vue_django/yoga_back/user/urls.py", line 3, in <module>
    from .views import *
  File "/home/yoga_vue_django/yoga_back/user/views.py", line 92
    <<<<<<< HEAD
     ^
IndentationError: expected an indented block
[2021-02-25 16:37:08 +0200] [30296] [INFO] Starting gunicorn 20.0.4
[2021-02-25 16:37:08 +0200] [30296] [INFO] Listening at: http://127.0.0.1:8000 (30296)
[2021-02-25 16:37:08 +0200] [30296] [INFO] Using worker: sync
[2021-02-25 16:37:08 +0200] [30299] [INFO] Booting worker with pid: 30299
[2021-02-25 16:37:08 +0200] [30301] [INFO] Booting worker with pid: 30301
[2021-02-25 16:37:08 +0200] [30302] [INFO] Booting worker with pid: 30302
Internal Server Error: /admin/
Traceback (most recent call last):
  File "/home/yoga/lib/python3.6/site-packages/django/core/handlers/exception.py", line 47, in inner
    response = get_response(request)
  File "/home/yoga/lib/python3.6/site-packages/django/core/handlers/base.py", line 167, in _get_response
    callback, callback_args, callback_kwargs = self.resolve_request(request)
  File "/home/yoga/lib/python3.6/site-packages/django/core/handlers/base.py", line 290, in resolve_request
    resolver_match = resolver.resolve(request.path_info)
  File "/home/yoga/lib/python3.6/site-packages/django/urls/resolvers.py", line 545, in resolve
    for pattern in self.url_patterns:
  File "/home/yoga/lib/python3.6/site-packages/django/utils/functional.py", line 48, in __get__
    res = instance.__dict__[self.name] = self.func(instance)
  File "/home/yoga/lib/python3.6/site-packages/django/urls/resolvers.py", line 589, in url_patterns
    patterns = getattr(self.urlconf_module, "urlpatterns", self.urlconf_module)
  File "/home/yoga/lib/python3.6/site-packages/django/utils/functional.py", line 48, in __get__
    res = instance.__dict__[self.name] = self.func(instance)
  File "/home/yoga/lib/python3.6/site-packages/django/urls/resolvers.py", line 582, in urlconf_module
    return import_module(self.urlconf_name)
  File "/usr/lib/python3.6/importlib/__init__.py", line 126, in import_module
    return _bootstrap._gcd_import(name[level:], package, level)
  File "<frozen importlib._bootstrap>", line 994, in _gcd_import
  File "<frozen importlib._bootstrap>", line 971, in _find_and_load
  File "<frozen importlib._bootstrap>", line 955, in _find_and_load_unlocked
  File "<frozen importlib._bootstrap>", line 665, in _load_unlocked
  File "<frozen importlib._bootstrap_external>", line 678, in exec_module
  File "<frozen importlib._bootstrap>", line 219, in _call_with_frames_removed
  File "/home/yoga_vue_django/yoga_back/yoga_back/urls.py", line 27, in <module>
    path('api/user/', include('user.urls')),
  File "/home/yoga/lib/python3.6/site-packages/django/urls/conf.py", line 34, in include
    urlconf_module = import_module(urlconf_module)
  File "/usr/lib/python3.6/importlib/__init__.py", line 126, in import_module
    return _bootstrap._gcd_import(name[level:], package, level)
  File "<frozen importlib._bootstrap>", line 994, in _gcd_import
  File "<frozen importlib._bootstrap>", line 971, in _find_and_load
  File "<frozen importlib._bootstrap>", line 955, in _find_and_load_unlocked
  File "<frozen importlib._bootstrap>", line 665, in _load_unlocked
  File "<frozen importlib._bootstrap_external>", line 678, in exec_module
  File "<frozen importlib._bootstrap>", line 219, in _call_with_frames_removed
  File "/home/yoga_vue_django/yoga_back/user/urls.py", line 3, in <module>
    from .views import *
  File "/home/yoga_vue_django/yoga_back/user/views.py", line 101
    'success': True,
             ^
SyntaxError: invalid syntax
Internal Server Error: /favicon.ico
Traceback (most recent call last):
  File "/home/yoga/lib/python3.6/site-packages/django/core/handlers/exception.py", line 47, in inner
    response = get_response(request)
  File "/home/yoga/lib/python3.6/site-packages/django/utils/deprecation.py", line 113, in __call__
    response = self.process_request(request)
  File "/home/yoga/lib/python3.6/site-packages/django/middleware/common.py", line 53, in process_request
    if self.should_redirect_with_slash(request):
  File "/home/yoga/lib/python3.6/site-packages/django/middleware/common.py", line 71, in should_redirect_with_slash
    not is_valid_path(request.path_info, urlconf) and
  File "/home/yoga/lib/python3.6/site-packages/django/urls/base.py", line 154, in is_valid_path
    resolve(path, urlconf)
  File "/home/yoga/lib/python3.6/site-packages/django/urls/base.py", line 25, in resolve
    return get_resolver(urlconf).resolve(path)
  File "/home/yoga/lib/python3.6/site-packages/django/urls/resolvers.py", line 545, in resolve
    for pattern in self.url_patterns:
  File "/home/yoga/lib/python3.6/site-packages/django/utils/functional.py", line 48, in __get__
    res = instance.__dict__[self.name] = self.func(instance)
  File "/home/yoga/lib/python3.6/site-packages/django/urls/resolvers.py", line 589, in url_patterns
    patterns = getattr(self.urlconf_module, "urlpatterns", self.urlconf_module)
  File "/home/yoga/lib/python3.6/site-packages/django/utils/functional.py", line 48, in __get__
    res = instance.__dict__[self.name] = self.func(instance)
  File "/home/yoga/lib/python3.6/site-packages/django/urls/resolvers.py", line 582, in urlconf_module
    return import_module(self.urlconf_name)
  File "/usr/lib/python3.6/importlib/__init__.py", line 126, in import_module
    return _bootstrap._gcd_import(name[level:], package, level)
  File "<frozen importlib._bootstrap>", line 994, in _gcd_import
  File "<frozen importlib._bootstrap>", line 971, in _find_and_load
  File "<frozen importlib._bootstrap>", line 955, in _find_and_load_unlocked
  File "<frozen importlib._bootstrap>", line 665, in _load_unlocked
  File "<frozen importlib._bootstrap_external>", line 678, in exec_module
  File "<frozen importlib._bootstrap>", line 219, in _call_with_frames_removed
  File "/home/yoga_vue_django/yoga_back/yoga_back/urls.py", line 27, in <module>
    path('api/user/', include('user.urls')),
  File "/home/yoga/lib/python3.6/site-packages/django/urls/conf.py", line 34, in include
    urlconf_module = import_module(urlconf_module)
  File "/usr/lib/python3.6/importlib/__init__.py", line 126, in import_module
    return _bootstrap._gcd_import(name[level:], package, level)
  File "<frozen importlib._bootstrap>", line 994, in _gcd_import
  File "<frozen importlib._bootstrap>", line 971, in _find_and_load
  File "<frozen importlib._bootstrap>", line 955, in _find_and_load_unlocked
  File "<frozen importlib._bootstrap>", line 665, in _load_unlocked
  File "<frozen importlib._bootstrap_external>", line 678, in exec_module
  File "<frozen importlib._bootstrap>", line 219, in _call_with_frames_removed
  File "/home/yoga_vue_django/yoga_back/user/urls.py", line 3, in <module>
    from .views import *
  File "/home/yoga_vue_django/yoga_back/user/views.py", line 101
    'success': True,
             ^
SyntaxError: invalid syntax
[2021-02-25 16:37:29 +0200] [30296] [INFO] Handling signal: term
[2021-02-25 14:37:29 +0000] [30299] [INFO] Worker exiting (pid: 30299)
[2021-02-25 14:37:29 +0000] [30301] [INFO] Worker exiting (pid: 30301)
[2021-02-25 14:37:29 +0000] [30302] [INFO] Worker exiting (pid: 30302)
[2021-02-25 16:37:29 +0200] [30296] [INFO] Shutting down: Master
[2021-02-25 16:37:29 +0200] [30315] [INFO] Starting gunicorn 20.0.4
[2021-02-25 16:37:29 +0200] [30315] [INFO] Listening at: http://127.0.0.1:8000 (30315)
[2021-02-25 16:37:29 +0200] [30315] [INFO] Using worker: sync
[2021-02-25 16:37:29 +0200] [30318] [INFO] Booting worker with pid: 30318
[2021-02-25 16:37:29 +0200] [30320] [INFO] Booting worker with pid: 30320
[2021-02-25 16:37:29 +0200] [30321] [INFO] Booting worker with pid: 30321
Internal Server Error: /admin/
Traceback (most recent call last):
  File "/home/yoga/lib/python3.6/site-packages/django/core/handlers/exception.py", line 47, in inner
    response = get_response(request)
  File "/home/yoga/lib/python3.6/site-packages/django/core/handlers/base.py", line 167, in _get_response
    callback, callback_args, callback_kwargs = self.resolve_request(request)
  File "/home/yoga/lib/python3.6/site-packages/django/core/handlers/base.py", line 290, in resolve_request
    resolver_match = resolver.resolve(request.path_info)
  File "/home/yoga/lib/python3.6/site-packages/django/urls/resolvers.py", line 545, in resolve
    for pattern in self.url_patterns:
  File "/home/yoga/lib/python3.6/site-packages/django/utils/functional.py", line 48, in __get__
    res = instance.__dict__[self.name] = self.func(instance)
  File "/home/yoga/lib/python3.6/site-packages/django/urls/resolvers.py", line 589, in url_patterns
    patterns = getattr(self.urlconf_module, "urlpatterns", self.urlconf_module)
  File "/home/yoga/lib/python3.6/site-packages/django/utils/functional.py", line 48, in __get__
    res = instance.__dict__[self.name] = self.func(instance)
  File "/home/yoga/lib/python3.6/site-packages/django/urls/resolvers.py", line 582, in urlconf_module
    return import_module(self.urlconf_name)
  File "/usr/lib/python3.6/importlib/__init__.py", line 126, in import_module
    return _bootstrap._gcd_import(name[level:], package, level)
  File "<frozen importlib._bootstrap>", line 994, in _gcd_import
  File "<frozen importlib._bootstrap>", line 971, in _find_and_load
  File "<frozen importlib._bootstrap>", line 955, in _find_and_load_unlocked
  File "<frozen importlib._bootstrap>", line 665, in _load_unlocked
  File "<frozen importlib._bootstrap_external>", line 678, in exec_module
  File "<frozen importlib._bootstrap>", line 219, in _call_with_frames_removed
  File "/home/yoga_vue_django/yoga_back/yoga_back/urls.py", line 27, in <module>
    path('api/user/', include('user.urls')),
  File "/home/yoga/lib/python3.6/site-packages/django/urls/conf.py", line 34, in include
    urlconf_module = import_module(urlconf_module)
  File "/usr/lib/python3.6/importlib/__init__.py", line 126, in import_module
    return _bootstrap._gcd_import(name[level:], package, level)
  File "<frozen importlib._bootstrap>", line 994, in _gcd_import
  File "<frozen importlib._bootstrap>", line 971, in _find_and_load
  File "<frozen importlib._bootstrap>", line 955, in _find_and_load_unlocked
  File "<frozen importlib._bootstrap>", line 665, in _load_unlocked
  File "<frozen importlib._bootstrap_external>", line 678, in exec_module
  File "<frozen importlib._bootstrap>", line 219, in _call_with_frames_removed
  File "/home/yoga_vue_django/yoga_back/user/urls.py", line 3, in <module>
    from .views import *
  File "/home/yoga_vue_django/yoga_back/user/views.py", line 7, in <module>
    from .serializers import UserSerializer, AdminSerializer
  File "/home/yoga_vue_django/yoga_back/user/serializers.py", line 20
    <<<<<<< HEAD
               ^
IndentationError: expected an indented block
Internal Server Error: /favicon.ico
Traceback (most recent call last):
  File "/home/yoga/lib/python3.6/site-packages/django/core/handlers/exception.py", line 47, in inner
    response = get_response(request)
  File "/home/yoga/lib/python3.6/site-packages/django/utils/deprecation.py", line 113, in __call__
    response = self.process_request(request)
  File "/home/yoga/lib/python3.6/site-packages/django/middleware/common.py", line 53, in process_request
    if self.should_redirect_with_slash(request):
  File "/home/yoga/lib/python3.6/site-packages/django/middleware/common.py", line 71, in should_redirect_with_slash
    not is_valid_path(request.path_info, urlconf) and
  File "/home/yoga/lib/python3.6/site-packages/django/urls/base.py", line 154, in is_valid_path
    resolve(path, urlconf)
  File "/home/yoga/lib/python3.6/site-packages/django/urls/base.py", line 25, in resolve
    return get_resolver(urlconf).resolve(path)
  File "/home/yoga/lib/python3.6/site-packages/django/urls/resolvers.py", line 545, in resolve
    for pattern in self.url_patterns:
  File "/home/yoga/lib/python3.6/site-packages/django/utils/functional.py", line 48, in __get__
    res = instance.__dict__[self.name] = self.func(instance)
  File "/home/yoga/lib/python3.6/site-packages/django/urls/resolvers.py", line 589, in url_patterns
    patterns = getattr(self.urlconf_module, "urlpatterns", self.urlconf_module)
  File "/home/yoga/lib/python3.6/site-packages/django/utils/functional.py", line 48, in __get__
    res = instance.__dict__[self.name] = self.func(instance)
  File "/home/yoga/lib/python3.6/site-packages/django/urls/resolvers.py", line 582, in urlconf_module
    return import_module(self.urlconf_name)
  File "/usr/lib/python3.6/importlib/__init__.py", line 126, in import_module
    return _bootstrap._gcd_import(name[level:], package, level)
  File "<frozen importlib._bootstrap>", line 994, in _gcd_import
  File "<frozen importlib._bootstrap>", line 971, in _find_and_load
  File "<frozen importlib._bootstrap>", line 955, in _find_and_load_unlocked
  File "<frozen importlib._bootstrap>", line 665, in _load_unlocked
  File "<frozen importlib._bootstrap_external>", line 678, in exec_module
  File "<frozen importlib._bootstrap>", line 219, in _call_with_frames_removed
  File "/home/yoga_vue_django/yoga_back/yoga_back/urls.py", line 27, in <module>
    path('api/user/', include('user.urls')),
  File "/home/yoga/lib/python3.6/site-packages/django/urls/conf.py", line 34, in include
    urlconf_module = import_module(urlconf_module)
  File "/usr/lib/python3.6/importlib/__init__.py", line 126, in import_module
    return _bootstrap._gcd_import(name[level:], package, level)
  File "<frozen importlib._bootstrap>", line 994, in _gcd_import
  File "<frozen importlib._bootstrap>", line 971, in _find_and_load
  File "<frozen importlib._bootstrap>", line 955, in _find_and_load_unlocked
  File "<frozen importlib._bootstrap>", line 665, in _load_unlocked
  File "<frozen importlib._bootstrap_external>", line 678, in exec_module
  File "<frozen importlib._bootstrap>", line 219, in _call_with_frames_removed
  File "/home/yoga_vue_django/yoga_back/user/urls.py", line 3, in <module>
    from .views import *
  File "/home/yoga_vue_django/yoga_back/user/views.py", line 7, in <module>
    from .serializers import UserSerializer, AdminSerializer
  File "/home/yoga_vue_django/yoga_back/user/serializers.py", line 20
    <<<<<<< HEAD
               ^
IndentationError: expected an indented block
[2021-02-25 16:37:49 +0200] [30315] [INFO] Handling signal: term
[2021-02-25 14:37:49 +0000] [30318] [INFO] Worker exiting (pid: 30318)
[2021-02-25 14:37:49 +0000] [30320] [INFO] Worker exiting (pid: 30320)
[2021-02-25 14:37:49 +0000] [30321] [INFO] Worker exiting (pid: 30321)
[2021-02-25 16:37:49 +0200] [30315] [INFO] Shutting down: Master
[2021-02-25 16:37:50 +0200] [30341] [INFO] Starting gunicorn 20.0.4
[2021-02-25 16:37:50 +0200] [30341] [INFO] Listening at: http://127.0.0.1:8000 (30341)
[2021-02-25 16:37:50 +0200] [30341] [INFO] Using worker: sync
[2021-02-25 16:37:50 +0200] [30344] [INFO] Booting worker with pid: 30344
[2021-02-25 16:37:50 +0200] [30346] [INFO] Booting worker with pid: 30346
[2021-02-25 16:37:50 +0200] [30347] [INFO] Booting worker with pid: 30347
Internal Server Error: /admin/
Traceback (most recent call last):
  File "/home/yoga/lib/python3.6/site-packages/django/contrib/sessions/backends/base.py", line 233, in _get_session
    return self._session_cache
AttributeError: 'SessionStore' object has no attribute '_session_cache'

During handling of the above exception, another exception occurred:

Traceback (most recent call last):
  File "/home/yoga/lib/python3.6/site-packages/django/db/backends/base/base.py", line 219, in ensure_connection
    self.connect()
  File "/home/yoga/lib/python3.6/site-packages/django/utils/asyncio.py", line 26, in inner
    return func(*args, **kwargs)
  File "/home/yoga/lib/python3.6/site-packages/django/db/backends/base/base.py", line 200, in connect
    self.connection = self.get_new_connection(conn_params)
  File "/home/yoga/lib/python3.6/site-packages/django/utils/asyncio.py", line 26, in inner
    return func(*args, **kwargs)
  File "/home/yoga/lib/python3.6/site-packages/django/db/backends/postgresql/base.py", line 187, in get_new_connection
    connection = Database.connect(**conn_params)
  File "/home/yoga/lib/python3.6/site-packages/psycopg2/__init__.py", line 127, in connect
    conn = _connect(dsn, connection_factory=connection_factory, **kwasync)
psycopg2.OperationalError: FATAL:  password authentication failed for user "postgres"
FATAL:  password authentication failed for user "postgres"


The above exception was the direct cause of the following exception:

Traceback (most recent call last):
  File "/home/yoga/lib/python3.6/site-packages/django/core/handlers/exception.py", line 47, in inner
    response = get_response(request)
  File "/home/yoga/lib/python3.6/site-packages/django/core/handlers/base.py", line 181, in _get_response
    response = wrapped_callback(request, *callback_args, **callback_kwargs)
  File "/home/yoga/lib/python3.6/site-packages/django/contrib/admin/sites.py", line 251, in wrapper
    return self.admin_view(view, cacheable)(*args, **kwargs)
  File "/home/yoga/lib/python3.6/site-packages/django/utils/decorators.py", line 130, in _wrapped_view
    response = view_func(request, *args, **kwargs)
  File "/home/yoga/lib/python3.6/site-packages/django/views/decorators/cache.py", line 44, in _wrapped_view_func
    response = view_func(request, *args, **kwargs)
  File "/home/yoga/lib/python3.6/site-packages/django/contrib/admin/sites.py", line 222, in inner
    if not self.has_permission(request):
  File "/home/yoga/lib/python3.6/site-packages/django/contrib/admin/sites.py", line 196, in has_permission
    return request.user.is_active and request.user.is_staff
  File "/home/yoga/lib/python3.6/site-packages/django/utils/functional.py", line 240, in inner
    self._setup()
  File "/home/yoga/lib/python3.6/site-packages/django/utils/functional.py", line 376, in _setup
    self._wrapped = self._setupfunc()
  File "/home/yoga/lib/python3.6/site-packages/django/contrib/auth/middleware.py", line 23, in <lambda>
    request.user = SimpleLazyObject(lambda: get_user(request))
  File "/home/yoga/lib/python3.6/site-packages/django/contrib/auth/middleware.py", line 11, in get_user
    request._cached_user = auth.get_user(request)
  File "/home/yoga/lib/python3.6/site-packages/django/contrib/auth/__init__.py", line 174, in get_user
    user_id = _get_user_session_key(request)
  File "/home/yoga/lib/python3.6/site-packages/django/contrib/auth/__init__.py", line 58, in _get_user_session_key
    return get_user_model()._meta.pk.to_python(request.session[SESSION_KEY])
  File "/home/yoga/lib/python3.6/site-packages/django/contrib/sessions/backends/base.py", line 65, in __getitem__
    return self._session[key]
  File "/home/yoga/lib/python3.6/site-packages/django/contrib/sessions/backends/base.py", line 238, in _get_session
    self._session_cache = self.load()
  File "/home/yoga/lib/python3.6/site-packages/django/contrib/sessions/backends/db.py", line 43, in load
    s = self._get_session_from_db()
  File "/home/yoga/lib/python3.6/site-packages/django/contrib/sessions/backends/db.py", line 34, in _get_session_from_db
    expire_date__gt=timezone.now()
  File "/home/yoga/lib/python3.6/site-packages/django/db/models/manager.py", line 85, in manager_method
    return getattr(self.get_queryset(), name)(*args, **kwargs)
  File "/home/yoga/lib/python3.6/site-packages/django/db/models/query.py", line 425, in get
    num = len(clone)
  File "/home/yoga/lib/python3.6/site-packages/django/db/models/query.py", line 269, in __len__
    self._fetch_all()
  File "/home/yoga/lib/python3.6/site-packages/django/db/models/query.py", line 1308, in _fetch_all
    self._result_cache = list(self._iterable_class(self))
  File "/home/yoga/lib/python3.6/site-packages/django/db/models/query.py", line 53, in __iter__
    results = compiler.execute_sql(chunked_fetch=self.chunked_fetch, chunk_size=self.chunk_size)
  File "/home/yoga/lib/python3.6/site-packages/django/db/models/sql/compiler.py", line 1154, in execute_sql
    cursor = self.connection.cursor()
  File "/home/yoga/lib/python3.6/site-packages/django/utils/asyncio.py", line 26, in inner
    return func(*args, **kwargs)
  File "/home/yoga/lib/python3.6/site-packages/django/db/backends/base/base.py", line 259, in cursor
    return self._cursor()
  File "/home/yoga/lib/python3.6/site-packages/django/db/backends/base/base.py", line 235, in _cursor
    self.ensure_connection()
  File "/home/yoga/lib/python3.6/site-packages/django/utils/asyncio.py", line 26, in inner
    return func(*args, **kwargs)
  File "/home/yoga/lib/python3.6/site-packages/django/db/backends/base/base.py", line 219, in ensure_connection
    self.connect()
  File "/home/yoga/lib/python3.6/site-packages/django/db/utils.py", line 90, in __exit__
    raise dj_exc_value.with_traceback(traceback) from exc_value
  File "/home/yoga/lib/python3.6/site-packages/django/db/backends/base/base.py", line 219, in ensure_connection
    self.connect()
  File "/home/yoga/lib/python3.6/site-packages/django/utils/asyncio.py", line 26, in inner
    return func(*args, **kwargs)
  File "/home/yoga/lib/python3.6/site-packages/django/db/backends/base/base.py", line 200, in connect
    self.connection = self.get_new_connection(conn_params)
  File "/home/yoga/lib/python3.6/site-packages/django/utils/asyncio.py", line 26, in inner
    return func(*args, **kwargs)
  File "/home/yoga/lib/python3.6/site-packages/django/db/backends/postgresql/base.py", line 187, in get_new_connection
    connection = Database.connect(**conn_params)
  File "/home/yoga/lib/python3.6/site-packages/psycopg2/__init__.py", line 127, in connect
    conn = _connect(dsn, connection_factory=connection_factory, **kwasync)
django.db.utils.OperationalError: FATAL:  password authentication failed for user "postgres"
FATAL:  password authentication failed for user "postgres"

Not Found: /favicon.ico
[2021-02-25 16:38:24 +0200] [30341] [INFO] Handling signal: term
[2021-02-25 14:38:24 +0000] [30344] [INFO] Worker exiting (pid: 30344)
[2021-02-25 14:38:24 +0000] [30346] [INFO] Worker exiting (pid: 30346)
[2021-02-25 14:38:24 +0000] [30347] [INFO] Worker exiting (pid: 30347)
[2021-02-25 16:38:24 +0200] [30341] [INFO] Shutting down: Master
[2021-02-25 16:38:24 +0200] [30384] [INFO] Starting gunicorn 20.0.4
[2021-02-25 16:38:24 +0200] [30384] [INFO] Listening at: http://127.0.0.1:8000 (30384)
[2021-02-25 16:38:24 +0200] [30384] [INFO] Using worker: sync
[2021-02-25 16:38:24 +0200] [30387] [INFO] Booting worker with pid: 30387
[2021-02-25 16:38:24 +0200] [30388] [INFO] Booting worker with pid: 30388
[2021-02-25 16:38:25 +0200] [30390] [INFO] Booting worker with pid: 30390
Not Found: /
Unsupported Media Type: /api/user/admin-login/
Unsupported Media Type: /api/user/admin-login/
Internal Server Error: /api/workout/create-workout/
Traceback (most recent call last):
  File "/home/yoga/lib/python3.6/site-packages/django/core/handlers/exception.py", line 47, in inner
    response = get_response(request)
  File "/home/yoga/lib/python3.6/site-packages/django/core/handlers/base.py", line 181, in _get_response
    response = wrapped_callback(request, *callback_args, **callback_kwargs)
  File "/home/yoga/lib/python3.6/site-packages/django/views/decorators/csrf.py", line 54, in wrapped_view
    return view_func(*args, **kwargs)
  File "/home/yoga/lib/python3.6/site-packages/django/views/generic/base.py", line 70, in view
    return self.dispatch(request, *args, **kwargs)
  File "/home/yoga/lib/python3.6/site-packages/rest_framework/views.py", line 509, in dispatch
    response = self.handle_exception(exc)
  File "/home/yoga/lib/python3.6/site-packages/rest_framework/views.py", line 469, in handle_exception
    self.raise_uncaught_exception(exc)
  File "/home/yoga/lib/python3.6/site-packages/rest_framework/views.py", line 480, in raise_uncaught_exception
    raise exc
  File "/home/yoga/lib/python3.6/site-packages/rest_framework/views.py", line 506, in dispatch
    response = handler(request, *args, **kwargs)
  File "/home/yoga_vue_django/yoga_back/workout/views.py", line 123, in post
    workout = WorkoutSerializer.create(self.request.data)
  File "/home/yoga_vue_django/yoga_back/workout/serializers.py", line 78, in create
    for trouble_id in ast.literal_eval(validated_data['troubles'][0]):
  File "/usr/lib/python3.6/ast.py", line 48, in literal_eval
    node_or_string = parse(node_or_string, mode='eval')
  File "/usr/lib/python3.6/ast.py", line 35, in parse
    return compile(source, filename, mode, PyCF_ONLY_AST)
  File "<unknown>", line 1
    [
    ^
SyntaxError: unexpected EOF while parsing
Internal Server Error: /api/workout/create-workout/
Traceback (most recent call last):
  File "/home/yoga/lib/python3.6/site-packages/django/core/handlers/exception.py", line 47, in inner
    response = get_response(request)
  File "/home/yoga/lib/python3.6/site-packages/django/core/handlers/base.py", line 181, in _get_response
    response = wrapped_callback(request, *callback_args, **callback_kwargs)
  File "/home/yoga/lib/python3.6/site-packages/django/views/decorators/csrf.py", line 54, in wrapped_view
    return view_func(*args, **kwargs)
  File "/home/yoga/lib/python3.6/site-packages/django/views/generic/base.py", line 70, in view
    return self.dispatch(request, *args, **kwargs)
  File "/home/yoga/lib/python3.6/site-packages/rest_framework/views.py", line 509, in dispatch
    response = self.handle_exception(exc)
  File "/home/yoga/lib/python3.6/site-packages/rest_framework/views.py", line 469, in handle_exception
    self.raise_uncaught_exception(exc)
  File "/home/yoga/lib/python3.6/site-packages/rest_framework/views.py", line 480, in raise_uncaught_exception
    raise exc
  File "/home/yoga/lib/python3.6/site-packages/rest_framework/views.py", line 506, in dispatch
    response = handler(request, *args, **kwargs)
  File "/home/yoga_vue_django/yoga_back/workout/views.py", line 123, in post
    workout = WorkoutSerializer.create(self.request.data)
  File "/home/yoga_vue_django/yoga_back/workout/serializers.py", line 78, in create
    for trouble_id in ast.literal_eval(validated_data['troubles'][0]):
  File "/usr/lib/python3.6/ast.py", line 48, in literal_eval
    node_or_string = parse(node_or_string, mode='eval')
  File "/usr/lib/python3.6/ast.py", line 35, in parse
    return compile(source, filename, mode, PyCF_ONLY_AST)
  File "<unknown>", line 1
    [
    ^
SyntaxError: unexpected EOF while parsing
Internal Server Error: /api/workout/create-workout/
Traceback (most recent call last):
  File "/home/yoga/lib/python3.6/site-packages/django/core/handlers/exception.py", line 47, in inner
    response = get_response(request)
  File "/home/yoga/lib/python3.6/site-packages/django/core/handlers/base.py", line 181, in _get_response
    response = wrapped_callback(request, *callback_args, **callback_kwargs)
  File "/home/yoga/lib/python3.6/site-packages/django/views/decorators/csrf.py", line 54, in wrapped_view
    return view_func(*args, **kwargs)
  File "/home/yoga/lib/python3.6/site-packages/django/views/generic/base.py", line 70, in view
    return self.dispatch(request, *args, **kwargs)
  File "/home/yoga/lib/python3.6/site-packages/rest_framework/views.py", line 509, in dispatch
    response = self.handle_exception(exc)
  File "/home/yoga/lib/python3.6/site-packages/rest_framework/views.py", line 469, in handle_exception
    self.raise_uncaught_exception(exc)
  File "/home/yoga/lib/python3.6/site-packages/rest_framework/views.py", line 480, in raise_uncaught_exception
    raise exc
  File "/home/yoga/lib/python3.6/site-packages/rest_framework/views.py", line 506, in dispatch
    response = handler(request, *args, **kwargs)
  File "/home/yoga_vue_django/yoga_back/workout/views.py", line 123, in post
    workout = WorkoutSerializer.create(self.request.data)
  File "/home/yoga_vue_django/yoga_back/workout/serializers.py", line 78, in create
    for trouble_id in ast.literal_eval(validated_data['troubles'][0]):
  File "/usr/lib/python3.6/ast.py", line 48, in literal_eval
    node_or_string = parse(node_or_string, mode='eval')
  File "/usr/lib/python3.6/ast.py", line 35, in parse
    return compile(source, filename, mode, PyCF_ONLY_AST)
  File "<unknown>", line 1
    [
    ^
SyntaxError: unexpected EOF while parsing
[2021-02-25 16:59:05 +0200] [30651] [INFO] Starting gunicorn 20.0.4
[2021-02-25 16:59:05 +0200] [30651] [INFO] Listening at: http://127.0.0.1:8000 (30651)
[2021-02-25 16:59:05 +0200] [30651] [INFO] Using worker: sync
[2021-02-25 16:59:05 +0200] [30654] [INFO] Booting worker with pid: 30654
[2021-02-25 16:59:06 +0200] [30656] [INFO] Booting worker with pid: 30656
[2021-02-25 16:59:06 +0200] [30657] [INFO] Booting worker with pid: 30657
Not Found: /robots.txt
Not Found: /
